Workbook

Sheet prova
A1: ID Silk | B1: Colonna1 | C1: Descrizione | D1: Severity | E1: Identificativo in relazione | F1: Numero ticket | G1: Priorità | H1: Servizio_digitale-pagina | I1: Requisito_criterio_violato | J1: Errore | K1: Soluzione | L1: Link screenshot / video | M1: AP | N1: PK
A2: D00110.1.3.1 | B2: =_xlfn.XLOOKUP(outTable[[#This Row],[ID Silk]],Tabella4[ID Silk],Tabella4[Titolo Defect],,0,1) -> Insurance Brocker - 10.1.3.1 Informazioni e correlazioni - D001 Modello CAI - LN (: | C2: Insurance Brocker - 10.1.3.1 Informazioni e correlazioni - D001 Modello CAI - LN (:: (#PDF0001)_x000D_ D001 Modello CAI - LN (_x000D_ Requisito WCAG: 1.3.1_x000D_ Disabilità afflitte: Blind;Deafblind;Mobility_x000D_ Impatto Utente: 2 - Serious_x000D_ _x000D_ Descrizione_x000D_ 001 - Utilizza i tag per specificare la struttura logica del PDF - Utilizza i tag per specificare la struttura logica del PDF (https://www.w3.org/TR/WCAG20-TECHS/pdf#pdf_notes_acc-sup_tagged)_x000D_ 002 - Fornire intestazioni contrassegnando il contenuto con tag di intestazione nei documenti PDF - Fornire intestazioni contrassegnando il contenuto con tag di intestazione nei documenti PDF (https://www.w3.org/WAI/WCAG22/Techniques/pdf/PDF9)_x000D_ 003 - Documento non contrassegnato come taggato - Documento non contrassegnato come taggato (https://www.w3.org/WAI/WCAG21/Techniques/pdf/PDF1)_x000D_ 004 - Oggetto di percorso non taggato - Oggetto di percorso non taggato (https://www.w3.org/WAI/WCAG21/Techniques/pdf/PDF1)_x000D_ 005 - Oggetto immagine non taggato - Oggetto immagine non taggato (https://www.w3.org/WAI/WCAG21/Techniques/pdf/PDF1)_x000D_ 006 - Oggetto testo non taggato - Oggetto testo non taggato (https://www.w3.org/WAI/WCAG21/Techniques/pdf/PDF1)_x000D_ _x000D_ Esempio di violazione individuata sull'oggetto:_x000D_ 001 - https://www.media.poste.it/1723b746-4914-4076-ba5f-26946e1806ed/web/modello-cai-ln con selettore_x000D_ 002 - https://www.media.poste.it/1723b746-4914-4076-ba5f-26946e1806ed/web/modello-cai-ln con selettore_x000D_ 003 - https://www.media.poste.it/1723b746-4914-4076-ba5f-26946e1806ed/web/modello-cai-ln con selettore_x000D_ 004 - https://www.media.poste.it/1723b746-4914-4076-ba5f-26946e1806ed/web/modello-cai-ln con selettore_x000D_ 005 - https://www.media.poste.it/1723b746-4914-4076-ba5f-26946e1806ed/web/modello-cai-ln con selettore_x000D_ 006 - https://www.media.poste.it/1723b746-4914-4076-ba5f-26946e1806ed/web/modello-cai-ln con selettore_x000D_ _x000D_ Possibile Metodologia Risolutiva:_x000D_ 001 - Cambiare la struttura del PDF a Tagged PDF_x000D_ 002 - I documenti pdf devono avere gli heading correttamente marcati: - Aggiungendo o modificando i tag heading su prodotti di modifica PDF - Creando documenti in programmi Word usando lo styling corretto per la conversione in PDF - Marcando gli heading usando elementi /Hn_x000D_ 003 - Contrassegnare tutto il documento come taggato per consentire l'accesso agli screen reader. In Adobe Acrobat, selezionare Aggiungi tag al documento._x000D_ 004 - Assicurarsi che tutti gli oggetti grafici di tipo percorso siano taggati. In Adobe Acrobat, selezionare l'oggetto e aggiungere un tag appropriato nella struttura dei tag._x000D_ 005 - Taggare ogni immagine e fornire una descrizione significativa per l'accesso tramite lettori di schermo. Usare Strumenti > Accessibilità > Aggiungi tag all'immagine_x000D_ 006 - Assicurarsi che tutti i blocchi di testo siano taggati correttamente nella struttura PDF per l’accesso con screen reader. In Adobe Acrobat, usare l'opzione Aggiungi tag al documento._x000D_ _x000D_ Occorrenze rilevate: 6_x000D_ _x000D_ Link al dettaglio requisito WCAG: https://www.w3.org/WAI/WCAG21/quickref/_x000D_ | D2: 2 - Serious | E2: (#PDF0001) | F2: 5958 | G2: 2 - Serious | H2: D001 Modello CAI - LN ( | I2: 10.1.3.1 | J2: 001 - Utilizza i tag per specificare la struttura logica del PDF - Utilizza i tag per specificare la struttura logica del PDF (https://www.w3.org/TR/WCAG20-TECHS/pdf#pdf_notes_acc-sup_tagged)_x000D_ 002 - Fornire intestazioni contrassegnando il contenuto con tag di intestazione nei documenti PDF - Fornire intestazioni contrassegnando il contenuto con tag di intestazione nei documenti PDF (https://www.w3.org/WAI/WCAG22/Techniques/pdf/PDF9)_x000D_ 003 - Documento non contrassegnato come taggato - Documento non contrassegnato come taggato (https://www.w3.org/WAI/WCAG21/Techniques/pdf/PDF1)_x000D_ 004 - Oggetto di percorso non taggato - Oggetto di percorso non taggato (https://www.w3.org/WAI/WCAG21/Techniques/pdf/PDF1)_x000D_ 005 - Oggetto immagine non taggato - Oggetto immagine non taggato (https://www.w3.org/WAI/WCAG21/Techniques/pdf/PDF1)_x000D_ 006 - Oggetto testo non taggato - Oggetto testo non taggato (https://www.w3.org/WAI/WCAG21/Techniques/pdf/PDF1) | K2: 001 - Cambiare la struttura del PDF a Tagged PDF_x000D_ 002 - I documenti pdf devono avere gli heading correttamente marcati: - Aggiungendo o modificando i tag heading su prodotti di modifica PDF - Creando documenti in programmi Word usando lo styling corretto per la conversione in PDF - Marcando gli heading usando elementi /Hn_x000D_ 003 - Contrassegnare tutto il documento come taggato per consentire l'accesso agli screen reader. In Adobe Acrobat, selezionare Aggiungi tag al documento._x000D_ 004 - Assicurarsi che tutti gli oggetti grafici di tipo percorso siano taggati. In Adobe Acrobat, selezionare l'oggetto e aggiungere un tag appropriato nella struttura dei tag._x000D_ 005 - Taggare ogni immagine e fornire una descrizione significativa per l'accesso tramite lettori di schermo. Usare Strumenti > Accessibilità > Aggiungi tag all'immagine_x000D_ 006 - Assicurarsi che tutti i blocchi di testo siano taggati correttamente nella struttura PDF per l’accesso con screen reader. In Adobe Acrobat, usare l'opzione Aggiungi tag al documento. | L2: 0 | M2: AP-00749 | N2: PK-02017
A3: D00110.1.3.2 | B3: =_xlfn.XLOOKUP(outTable[[#This Row],[ID Silk]],Tabella4[ID Silk],Tabella4[Titolo Defect],,0,1) -> Insurance Brocker - 10.1.3.2 Sequenza significativa - D001 Modello CAI - LN (: | C3: Insurance Brocker - 10.1.3.2 Sequenza significativa - D001 Modello CAI - LN (:: (#PDF0003)_x000D_ D001 Modello CAI - LN (_x000D_ Requisito WCAG: 1.3.2_x000D_ Disabilità afflitte: Blind;Deafblind;Mobility_x000D_ Impatto Utente: 1 - Critical_x000D_ _x000D_ Descrizione_x000D_ 001 - Garantire il corretto ordine di tabulazione e di lettura nei documenti PDF - Garantire il corretto ordine di tabulazione e di lettura nei documenti PDF (https://www.w3.org/WAI/WCAG22/Techniques/pdf/PDF3)_x000D_ _x000D_ Esempio di violazione individuata sull'oggetto:_x000D_ 001 - https://www.media.poste.it/1723b746-4914-4076-ba5f-26946e1806ed/web/modello-cai-ln con selettore_x000D_ _x000D_ Possibile Metodologia Risolutiva:_x000D_ 001 - Imposta l'ordine di scorrimento degli elementi su una pagina utilizzando l'opzione "Struttura documento"_x000D_ _x000D_ Occorrenze rilevate: 1_x000D_ _x000D_ Link al dettaglio requisito WCAG: https://www.w3.org/WAI/WCAG21/quickref/_x000D_ | D3: 1 - Critical | E3: (#PDF0003) | F3: 5959 | G3: 1 - Critical | H3: D001 Modello CAI - LN ( | I3: 10.1.3.2 | J3: 001 - Garantire il corretto ordine di tabulazione e di lettura nei documenti PDF - Garantire il corretto ordine di tabulazione e di lettura nei documenti PDF (https://www.w3.org/WAI/WCAG22/Techniques/pdf/PDF3) | K3: 001 - Imposta l'ordine di scorrimento degli elementi su una pagina utilizzando l'opzione "Struttura documento" | L3: 0 | M3: AP-00749 | N3: PK-02017
A4: D00110.1.4.3 | B4: =_xlfn.XLOOKUP(outTable[[#This Row],[ID Silk]],Tabella4[ID Silk],Tabella4[Titolo Defect],,0,1) -> Insurance Brocker - 10.1.4.3 Contrasto (minimo) - D001 Modello CAI - LN (: | C4: Insurance Brocker - 10.1.4.3 Contrasto (minimo) - D001 Modello CAI - LN (:: (#PDF0010)_x000D_ D001 Modello CAI - LN (_x000D_ Requisito WCAG: 1.4.3_x000D_ Disabilità afflitte: Blind;Cognitive;Deafblind_x000D_ Impatto Utente: 2 - Serious_x000D_ _x000D_ Descrizione_x000D_ 001 - Testo con contrasto insufficiente - Testo con contrasto insufficiente (https://www.w3.org/WAI/WCAG21/Techniques/general/G18)_x000D_ _x000D_ Esempio di violazione individuata sull'oggetto:_x000D_ 001 - https://www.media.poste.it/1723b746-4914-4076-ba5f-26946e1806ed/web/modello-cai-ln con selettore_x000D_ _x000D_ Possibile Metodologia Risolutiva:_x000D_ 001 - Regolare il contrasto tra testo e sfondo, assicurandosi che rispetti il rapporto minimo di contrasto di 4.5:1. Modificare il colore del testo o dello sfondo nel software di editing._x000D_ _x000D_ Occorrenze rilevate: 1_x000D_ _x000D_ Link al dettaglio requisito WCAG: https://www.w3.org/WAI/WCAG21/quickref/_x000D_ | D4: 2 - Serious | E4: (#PDF0010) | F4: 5960 | G4: 2 - Serious | H4: D001 Modello CAI - LN ( | I4: 10.1.4.3 | J4: 001 - Testo con contrasto insufficiente - Testo con contrasto insufficiente (https://www.w3.org/WAI/WCAG21/Techniques/general/G18) | K4: 001 - Regolare il contrasto tra testo e sfondo, assicurandosi che rispetti il rapporto minimo di contrasto di 4.5:1. Modificare il colore del testo o dello sfondo nel software di editing. | L4: 0 | M4: AP-00749 | N4: PK-02017
A5: D00110.2.4.2 | B5: =_xlfn.XLOOKUP(outTable[[#This Row],[ID Silk]],Tabella4[ID Silk],Tabella4[Titolo Defect],,0,1) -> Insurance Brocker - 10.2.4.2 Titolazione della pagina - D001 Modello CAI - LN (: | C5: Insurance Brocker - 10.2.4.2 Titolazione della pagina - D001 Modello CAI - LN (:: (#PDF0004)_x000D_ D001 Modello CAI - LN (_x000D_ Requisito WCAG: 2.4.2_x000D_ Disabilità afflitte: Blind;Deafblind_x000D_ Impatto Utente: 4 - Minor_x000D_ _x000D_ Descrizione_x000D_ 001 - Specificare il titolo del documento utilizzando la voce Titolo nel dizionario delle informazioni di un documento PDF - Specificare il titolo del documento utilizzando la voce Titolo nel dizionario delle informazioni di un documento PDF (https://www.w3.org/WAI/WCAG22/Techniques/pdf/PDF18)_x000D_ 002 - Titolo mancante nei metadati XMP del documento - Titolo mancante nei metadati XMP del documento (https://www.w3.org/WAI/WCAG21/Techniques/general/G88)_x000D_ 003 - "DisplayDocTitle" non impostato - "DisplayDocTitle" non impostato (https://www.w3.org/WAI/WCAG21/Techniques/general/G88)_x000D_ _x000D_ Esempio di violazione individuata sull'oggetto:_x000D_ 001 - https://www.media.poste.it/1723b746-4914-4076-ba5f-26946e1806ed/web/modello-cai-ln con selettore_x000D_ 002 - https://www.media.poste.it/1723b746-4914-4076-ba5f-26946e1806ed/web/modello-cai-ln con selettore_x000D_ 003 - https://www.media.poste.it/1723b746-4914-4076-ba5f-26946e1806ed/web/modello-cai-ln con selettore_x000D_ _x000D_ Possibile Metodologia Risolutiva:_x000D_ 001 - Imposta il nuovo titolo PDF_x000D_ 002 - Aggiungere un titolo descrittivo nei metadati del documento (XMP), che aiuti gli utenti a identificare facilmente il contenuto. In Adobe Acrobat, andare su File > Proprietà > Descrizione e inserire un titolo._x000D_ 003 - Impostare l’opzione "DisplayDocTitle" per mostrare il titolo del documento anziché il nome file. In Acrobat, andare su File > Proprietà > Visualizzazione iniziale e selezionare “Mostra titolo documento”._x000D_ _x000D_ Occorrenze rilevate: 3_x000D_ _x000D_ Link al dettaglio requisito WCAG: https://www.w3.org/WAI/WCAG21/quickref/_x000D_ | D5: 4 - Minor | E5: (#PDF0004) | F5: 5961 | G5: 4 - Minor | H5: D001 Modello CAI - LN ( | I5: 10.2.4.2 | J5: 001 - Specificare il titolo del documento utilizzando la voce Titolo nel dizionario delle informazioni di un documento PDF - Specificare il titolo del documento utilizzando la voce Titolo nel dizionario delle informazioni di un documento PDF (https://www.w3.org/WAI/WCAG22/Techniques/pdf/PDF18)_x000D_ 002 - Titolo mancante nei metadati XMP del documento - Titolo mancante nei metadati XMP del documento (https://www.w3.org/WAI/WCAG21/Techniques/general/G88)_x000D_ 003 - "DisplayDocTitle" non impostato - "DisplayDocTitle" non impostato (https://www.w3.org/WAI/WCAG21/Techniques/general/G88) | K5: 001 - Imposta il nuovo titolo PDF_x000D_ 002 - Aggiungere un titolo descrittivo nei metadati del documento (XMP), che aiuti gli utenti a identificare facilmente il contenuto. In Adobe Acrobat, andare su File > Proprietà > Descrizione e inserire un titolo._x000D_ 003 - Impostare l’opzione "DisplayDocTitle" per mostrare il titolo del documento anziché il nome file. In Acrobat, andare su File > Proprietà > Visualizzazione iniziale e selezionare “Mostra titolo documento”. | L5: 0 | M5: AP-00749 | N5: PK-02017
A6: D00110.3.1.1 | B6: =_xlfn.XLOOKUP(outTable[[#This Row],[ID Silk]],Tabella4[ID Silk],Tabella4[Titolo Defect],,0,1) -> Insurance Brocker - 10.3.1.1 Lingua della pagina - D001 Modello CAI - LN (: | C6: Insurance Brocker - 10.3.1.1 Lingua della pagina - D001 Modello CAI - LN (:: (#PDF0005)_x000D_ D001 Modello CAI - LN (_x000D_ Requisito WCAG: 3.1.1_x000D_ Disabilità afflitte: Blind;Cognitive;Deafblind_x000D_ Impatto Utente: 3 - Moderate_x000D_ _x000D_ Descrizione_x000D_ 001 - Impostazione della lingua predefinita utilizzando la voce /Lang nel catalogo documenti di un documento PDF - Impostazione della lingua predefinita utilizzando la voce /Lang nel catalogo documenti di un documento PDF (https://www.w3.org/WAI/WCAG22/Techniques/pdf/PDF16)_x000D_ 002 - I metadati della lingua del documento contengono un errore di sintassi - I metadati della lingua del documento contengono un errore di sintassi (https://www.w3.org/WAI/WCAG21/Techniques/html/H57)_x000D_ _x000D_ Esempio di violazione individuata sull'oggetto:_x000D_ 001 - https://www.media.poste.it/1723b746-4914-4076-ba5f-26946e1806ed/web/modello-cai-ln con selettore_x000D_ 002 - https://www.media.poste.it/1723b746-4914-4076-ba5f-26946e1806ed/web/modello-cai-ln con selettore_x000D_ _x000D_ Possibile Metodologia Risolutiva:_x000D_ 001 - Seleziona la lingua principale del PDF_x000D_ 002 - Correggere l'errore di sintassi nei metadati della lingua per consentire ai lettori di schermo di riconoscere correttamente la lingua._x000D_ _x000D_ Occorrenze rilevate: 2_x000D_ _x000D_ Link al dettaglio requisito WCAG: https://www.w3.org/WAI/WCAG21/quickref/_x000D_ | D6: 3 - Moderate | E6: (#PDF0005) | F6: 5962 | G6: 3 - Moderate | H6: D001 Modello CAI - LN ( | I6: 10.3.1.1 | J6: 001 - Impostazione della lingua predefinita utilizzando la voce /Lang nel catalogo documenti di un documento PDF - Impostazione della lingua predefinita utilizzando la voce /Lang nel catalogo documenti di un documento PDF (https://www.w3.org/WAI/WCAG22/Techniques/pdf/PDF16)_x000D_ 002 - I metadati della lingua del documento contengono un errore di sintassi - I metadati della lingua del documento contengono un errore di sintassi (https://www.w3.org/WAI/WCAG21/Techniques/html/H57) | K6: 001 - Seleziona la lingua principale del PDF_x000D_ 002 - Correggere l'errore di sintassi nei metadati della lingua per consentire ai lettori di schermo di riconoscere correttamente la lingua. | L6: 0 | M6: AP-00749 | N6: PK-02017
A7: D00110.3.1.2 | B7: =_xlfn.XLOOKUP(outTable[[#This Row],[ID Silk]],Tabella4[ID Silk],Tabella4[Titolo Defect],,0,1) -> Insurance Brocker - 10.3.1.2 Parti in lingua - D001 Modello CAI - LN (: | C7: Insurance Brocker - 10.3.1.2 Parti in lingua - D001 Modello CAI - LN (:: (#PDF0014)_x000D_ D001 Modello CAI - LN (_x000D_ Requisito WCAG: 3.1.2_x000D_ Disabilità afflitte: Blind;Cognitive;Deafblind_x000D_ Impatto Utente: 2 - Serious_x000D_ _x000D_ Descrizione_x000D_ 001 - La lingua naturale per un oggetto di testo non può essere determinata. - La lingua naturale per un oggetto di testo non può essere determinata. (https://www.w3.org/TR/WCAG20-TECHS/PDF19.html)_x000D_ _x000D_ Esempio di violazione individuata sull'oggetto:_x000D_ 001 - https://www.media.poste.it/1723b746-4914-4076-ba5f-26946e1806ed/web/modello-cai-ln con selettore_x000D_ _x000D_ Possibile Metodologia Risolutiva:_x000D_ 001 - In Adobe Acrobat Pro, vai su File > Proprietà > Avanzate e imposta la lingua predefinita del documento. Usa strumenti di verifica per controllare che tutti gli oggetti di testo ereditino correttamente questa impostazione._x000D_ _x000D_ Occorrenze rilevate: 1_x000D_ _x000D_ Link al dettaglio requisito WCAG: https://www.w3.org/WAI/WCAG21/quickref/_x000D_ | D7: 2 - Serious | E7: (#PDF0014) | F7: 5963 | G7: 2 - Serious | H7: D001 Modello CAI - LN ( | I7: 10.3.1.2 | J7: 001 - La lingua naturale per un oggetto di testo non può essere determinata. - La lingua naturale per un oggetto di testo non può essere determinata. (https://www.w3.org/TR/WCAG20-TECHS/PDF19.html) | K7: 001 - In Adobe Acrobat Pro, vai su File > Proprietà > Avanzate e imposta la lingua predefinita del documento. Usa strumenti di verifica per controllare che tutti gli oggetti di testo ereditino correttamente questa impostazione. | L7: 0 | M7: AP-00749 | N7: PK-02017
A8: D00210.1.3.1 | B8: =_xlfn.XLOOKUP(outTable[[#This Row],[ID Silk]],Tabella4[ID Silk],Tabella4[Titolo Defect],,0,1) -> Insurance Brocker - 10.1.3.1 Informazioni e correlazioni - D002 Modello CAI - GN: | C8: Insurance Brocker - 10.1.3.1 Informazioni e correlazioni - D002 Modello CAI - GN:: (#PDF0015)_x000D_ D002 Modello CAI - GN_x000D_ Requisito WCAG: 1.3.1_x000D_ Disabilità afflitte: Blind;Deafblind;Mobility_x000D_ Impatto Utente: 3 - Moderate_x000D_ _x000D_ Descrizione_x000D_ 001 - Utilizza i tag per specificare la struttura logica del PDF - Utilizza i tag per specificare la struttura logica del PDF (https://www.w3.org/TR/WCAG20-TECHS/pdf#pdf_notes_acc-sup_tagged)_x000D_ 002 - Fornire intestazioni contrassegnando il contenuto con tag di intestazione nei documenti PDF - Fornire intestazioni contrassegnando il contenuto con tag di intestazione nei documenti PDF (https://www.w3.org/WAI/WCAG22/Techniques/pdf/PDF9)_x000D_ 003 - Documento non contrassegnato come taggato - Documento non contrassegnato come taggato (https://www.w3.org/WAI/WCAG21/Techniques/pdf/PDF1)_x000D_ 004 - Oggetto di percorso non taggato - Oggetto di percorso non taggato (https://www.w3.org/WAI/WCAG21/Techniques/pdf/PDF1)_x000D_ 005 - Oggetto immagine non taggato - Oggetto immagine non taggato (https://www.w3.org/WAI/WCAG21/Techniques/pdf/PDF1)_x000D_ 006 - Oggetto testo non taggato - Oggetto testo non taggato (https://www.w3.org/WAI/WCAG21/Techniques/pdf/PDF1)_x000D_ 007 - Font non incorporato - Font non incorporato (https://www.w3.org/WAI/WCAG22/Techniques/general/G117.html)_x000D_ _x000D_ Esempio di violazione individuata sull'oggetto:_x000D_ 001 - https://www.media.poste.it/6a7ffb23-48ca-4da0-8809-5d99d243adb4/web/modello-cai-gtel con selettore_x000D_ 002 - https://www.media.poste.it/6a7ffb23-48ca-4da0-8809-5d99d243adb4/web/modello-cai-gtel con selettore_x000D_ 003 - https://www.media.poste.it/6a7ffb23-48ca-4da0-8809-5d99d243adb4/web/modello-cai-gtel con selettore_x000D_ 004 - https://www.media.poste.it/6a7ffb23-48ca-4da0-8809-5d99d243adb4/web/modello-cai-gtel con selettore_x000D_ 005 - https://www.media.poste.it/6a7ffb23-48ca-4da0-8809-5d99d243adb4/web/modello-cai-gtel con selettore_x000D_ 006 - https://www.media.poste.it/6a7ffb23-48ca-4da0-8809-5d99d243adb4/web/modello-cai-gtel con selettore_x000D_ 007 - https://www.media.poste.it/6a7ffb23-48ca-4da0-8809-5d99d243adb4/web/modello-cai-gtel con selettore_x000D_ _x000D_ Possibile Metodologia Risolutiva:_x000D_ 001 - Cambiare la struttura del PDF a Tagged PDF_x000D_ 002 - I documenti pdf devono avere gli heading correttamente marcati: - Aggiungendo o modificando i tag heading su prodotti di modifica PDF - Creando documenti in programmi Word usando lo styling corretto per la conversione in PDF - Marcando gli heading usando elementi /Hn_x000D_ 003 - Contrassegnare tutto il documento come taggato per consentire l'accesso agli screen reader. In Adobe Acrobat, selezionare Aggiungi tag al documento._x000D_ 004 - Assicurarsi che tutti gli oggetti grafici di tipo percorso siano taggati. In Adobe Acrobat, selezionare l'oggetto e aggiungere un tag appropriato nella struttura dei tag._x000D_ 005 - Taggare ogni immagine e fornire una descrizione significativa per l'accesso tramite lettori di schermo. Usare Strumenti > Accessibilità > Aggiungi tag all'immagine_x000D_ 006 - Assicurarsi che tutti i blocchi di testo siano taggati correttamente nella struttura PDF per l’accesso con screen reader. In Adobe Acrobat, usare l'opzione Aggiungi tag al documento._x000D_ 007 - Non comunicare informazioni solo tramite cambi visivi. Utilizzare font, bold face, font size, underline e altri attributi di testo necessita che le informazioni comunicate visivamente debbano essere comunicate altrove anche via testo_x000D_ _x000D_ Occorrenze rilevate: 7_x000D_ _x000D_ Link al dettaglio requisito WCAG: https://www.w3.org/WAI/WCAG21/quickref/_x000D_ | D8: 3 - Moderate | E8: (#PDF0015) | F8: 5964 | G8: 3 - Moderate | H8: D002 Modello CAI - GN | I8: 10.1.3.1 | J8: 001 - Utilizza i tag per specificare la struttura logica del PDF - Utilizza i tag per specificare la struttura logica del PDF (https://www.w3.org/TR/WCAG20-TECHS/pdf#pdf_notes_acc-sup_tagged)_x000D_ 002 - Fornire intestazioni contrassegnando il contenuto con tag di intestazione nei documenti PDF - Fornire intestazioni contrassegnando il contenuto con tag di intestazione nei documenti PDF (https://www.w3.org/WAI/WCAG22/Techniques/pdf/PDF9)_x000D_ 003 - Documento non contrassegnato come taggato - Documento non contrassegnato come taggato (https://www.w3.org/WAI/WCAG21/Techniques/pdf/PDF1)_x000D_ 004 - Oggetto di percorso non taggato - Oggetto di percorso non taggato (https://www.w3.org/WAI/WCAG21/Techniques/pdf/PDF1)_x000D_ 005 - Oggetto immagine non taggato - Oggetto immagine non taggato (https://www.w3.org/WAI/WCAG21/Techniques/pdf/PDF1)_x000D_ 006 - Oggetto testo non taggato - Oggetto testo non taggato (https://www.w3.org/WAI/WCAG21/Techniques/pdf/PDF1)_x000D_ 007 - Font non incorporato - Font non incorporato (https://www.w3.org/WAI/WCAG22/Techniques/general/G117.html) | K8: 001 - Cambiare la struttura del PDF a Tagged PDF_x000D_ 002 - I documenti pdf devono avere gli heading correttamente marcati: - Aggiungendo o modificando i tag heading su prodotti di modifica PDF - Creando documenti in programmi Word usando lo styling corretto per la conversione in PDF - Marcando gli heading usando elementi /Hn_x000D_ 003 - Contrassegnare tutto il documento come taggato per consentire l'accesso agli screen reader. In Adobe Acrobat, selezionare Aggiungi tag al documento._x000D_ 004 - Assicurarsi che tutti gli oggetti grafici di tipo percorso siano taggati. In Adobe Acrobat, selezionare l'oggetto e aggiungere un tag appropriato nella struttura dei tag._x000D_ 005 - Taggare ogni immagine e fornire una descrizione significativa per l'accesso tramite lettori di schermo. Usare Strumenti > Accessibilità > Aggiungi tag all'immagine_x000D_ 006 - Assicurarsi che tutti i blocchi di testo siano taggati correttamente nella struttura PDF per l’accesso con screen reader. In Adobe Acrobat, usare l'opzione Aggiungi tag al documento._x000D_ 007 - Non comunicare informazioni solo tramite cambi visivi. Utilizzare font, bold face, font size, underline e altri attributi di testo necessita che le informazioni comunicate visivamente debbano essere comunicate altrove anche via testo | L8: 0 | M8: AP-00749 | N8: PK-02017
A9: D00210.1.3.2 | B9: =_xlfn.XLOOKUP(outTable[[#This Row],[ID Silk]],Tabella4[ID Silk],Tabella4[Titolo Defect],,0,1) -> Insurance Brocker - 10.1.3.2 Sequenza significativa - D002 Modello CAI - GN: | C9: Insurance Brocker - 10.1.3.2 Sequenza significativa - D002 Modello CAI - GN:: (#PDF0017)_x000D_ D002 Modello CAI - GN_x000D_ Requisito WCAG: 1.3.2_x000D_ Disabilità afflitte: Blind;Deafblind;Mobility_x000D_ Impatto Utente: 1 - Critical_x000D_ _x000D_ Descrizione_x000D_ 001 - Garantire il corretto ordine di tabulazione e di lettura nei documenti PDF - Garantire il corretto ordine di tabulazione e di lettura nei documenti PDF (https://www.w3.org/WAI/WCAG22/Techniques/pdf/PDF3)_x000D_ _x000D_ Esempio di violazione individuata sull'oggetto:_x000D_ 001 - https://www.media.poste.it/6a7ffb23-48ca-4da0-8809-5d99d243adb4/web/modello-cai-gtel con selettore_x000D_ _x000D_ Possibile Metodologia Risolutiva:_x000D_ 001 - Imposta l'ordine di scorrimento degli elementi su una pagina utilizzando l'opzione "Struttura documento"_x000D_ _x000D_ Occorrenze rilevate: 1_x000D_ _x000D_ Link al dettaglio requisito WCAG: https://www.w3.org/WAI/WCAG21/quickref/_x000D_ | D9: 1 - Critical | E9: (#PDF0017) | F9: 5965 | G9: 1 - Critical | H9: D002 Modello CAI - GN | I9: 10.1.3.2 | J9: 001 - Garantire il corretto ordine di tabulazione e di lettura nei documenti PDF - Garantire il corretto ordine di tabulazione e di lettura nei documenti PDF (https://www.w3.org/WAI/WCAG22/Techniques/pdf/PDF3) | K9: 001 - Imposta l'ordine di scorrimento degli elementi su una pagina utilizzando l'opzione "Struttura documento" | L9: 0 | M9: AP-00749 | N9: PK-02017
A10: D00210.1.4.3 | B10: =_xlfn.XLOOKUP(outTable[[#This Row],[ID Silk]],Tabella4[ID Silk],Tabella4[Titolo Defect],,0,1) -> Insurance Brocker - 10.1.4.3 Contrasto (minimo) - D002 Modello CAI - GN: | C10: Insurance Brocker - 10.1.4.3 Contrasto (minimo) - D002 Modello CAI - GN:: (#PDF0025)_x000D_ D002 Modello CAI - GN_x000D_ Requisito WCAG: 1.4.3_x000D_ Disabilità afflitte: Blind;Cognitive;Deafblind_x000D_ Impatto Utente: 2 - Serious_x000D_ _x000D_ Descrizione_x000D_ 001 - Testo con contrasto insufficiente - Testo con contrasto insufficiente (https://www.w3.org/WAI/WCAG21/Techniques/general/G18)_x000D_ _x000D_ Esempio di violazione individuata sull'oggetto:_x000D_ 001 - https://www.media.poste.it/6a7ffb23-48ca-4da0-8809-5d99d243adb4/web/modello-cai-gtel con selettore_x000D_ _x000D_ Possibile Metodologia Risolutiva:_x000D_ 001 - Regolare il contrasto tra testo e sfondo, assicurandosi che rispetti il rapporto minimo di contrasto di 4.5:1. Modificare il colore del testo o dello sfondo nel software di editing._x000D_ _x000D_ Occorrenze rilevate: 1_x000D_ _x000D_ Link al dettaglio requisito WCAG: https://www.w3.org/WAI/WCAG21/quickref/_x000D_ | D10: 2 - Serious | E10: (#PDF0025) | F10: 5968 | G10: 2 - Serious | H10: D002 Modello CAI - GN | I10: 10.1.4.3 | J10: 001 - Testo con contrasto insufficiente - Testo con contrasto insufficiente (https://www.w3.org/WAI/WCAG21/Techniques/general/G18) | K10: 001 - Regolare il contrasto tra testo e sfondo, assicurandosi che rispetti il rapporto minimo di contrasto di 4.5:1. Modificare il colore del testo o dello sfondo nel software di editing. | L10: 0 | M10: AP-00749 | N10: PK-02017
A11: D00210.2.4.2 | B11: =_xlfn.XLOOKUP(outTable[[#This Row],[ID Silk]],Tabella4[ID Silk],Tabella4[Titolo Defect],,0,1) -> Insurance Brocker - 10.2.4.2 Titolazione della pagina - D002 Modello CAI - GN: | C11: Insurance Brocker - 10.2.4.2 Titolazione della pagina - D002 Modello CAI - GN:: (#PDF0018)_x000D_ D002 Modello CAI - GN_x000D_ Requisito WCAG: 2.4.2_x000D_ Disabilità afflitte: Blind;Deafblind_x000D_ Impatto Utente: 4 - Minor_x000D_ _x000D_ Descrizione_x000D_ 001 - Specificare il titolo del documento utilizzando la voce Titolo nel dizionario delle informazioni di un documento PDF - Specificare il titolo del documento utilizzando la voce Titolo nel dizionario delle informazioni di un documento PDF (https://www.w3.org/WAI/WCAG22/Techniques/pdf/PDF18)_x000D_ 002 - "DisplayDocTitle" non impostato - "DisplayDocTitle" non impostato (https://www.w3.org/WAI/WCAG21/Techniques/general/G88)_x000D_ _x000D_ Esempio di violazione individuata sull'oggetto:_x000D_ 001 - https://www.media.poste.it/6a7ffb23-48ca-4da0-8809-5d99d243adb4/web/modello-cai-gtel con selettore_x000D_ 002 - https://www.media.poste.it/6a7ffb23-48ca-4da0-8809-5d99d243adb4/web/modello-cai-gtel con selettore_x000D_ _x000D_ Possibile Metodologia Risolutiva:_x000D_ 001 - Imposta il nuovo titolo PDF_x000D_ 002 - Impostare l’opzione "DisplayDocTitle" per mostrare il titolo del documento anziché il nome file. In Acrobat, andare su File > Proprietà > Visualizzazione iniziale e selezionare “Mostra titolo documento”._x000D_ _x000D_ Occorrenze rilevate: 2_x000D_ _x000D_ Link al dettaglio requisito WCAG: https://www.w3.org/WAI/WCAG21/quickref/_x000D_ | D11: 4 - Minor | E11: (#PDF0018) | F11: 5969 | G11: 4 - Minor | H11: D002 Modello CAI - GN | I11: 10.2.4.2 | J11: 001 - Specificare il titolo del documento utilizzando la voce Titolo nel dizionario delle informazioni di un documento PDF - Specificare il titolo del documento utilizzando la voce Titolo nel dizionario delle informazioni di un documento PDF (https://www.w3.org/WAI/WCAG22/Techniques/pdf/PDF18)_x000D_ 002 - "DisplayDocTitle" non impostato - "DisplayDocTitle" non impostato (https://www.w3.org/WAI/WCAG21/Techniques/general/G88) | K11: 001 - Imposta il nuovo titolo PDF_x000D_ 002 - Impostare l’opzione "DisplayDocTitle" per mostrare il titolo del documento anziché il nome file. In Acrobat, andare su File > Proprietà > Visualizzazione iniziale e selezionare “Mostra titolo documento”. | L11: 0 | M11: AP-00749 | N11: PK-02017
A12: D00210.3.1.1 | B12: =_xlfn.XLOOKUP(outTable[[#This Row],[ID Silk]],Tabella4[ID Silk],Tabella4[Titolo Defect],,0,1) -> Insurance Brocker - 10.3.1.1 Lingua della pagina - D002 Modello CAI - GN: | C12: Insurance Brocker - 10.3.1.1 Lingua della pagina - D002 Modello CAI - GN:: (#PDF0019)_x000D_ D002 Modello CAI - GN_x000D_ Requisito WCAG: 3.1.1_x000D_ Disabilità afflitte: Blind;Cognitive;Deafblind_x000D_ Impatto Utente: 3 - Moderate_x000D_ _x000D_ Descrizione_x000D_ 001 - Impostazione della lingua predefinita utilizzando la voce /Lang nel catalogo documenti di un documento PDF - Impostazione della lingua predefinita utilizzando la voce /Lang nel catalogo documenti di un documento PDF (https://www.w3.org/WAI/WCAG22/Techniques/pdf/PDF16)_x000D_ 002 - I metadati della lingua del documento contengono un errore di sintassi - I metadati della lingua del documento contengono un errore di sintassi (https://www.w3.org/WAI/WCAG21/Techniques/html/H57)_x000D_ _x000D_ Esempio di violazione individuata sull'oggetto:_x000D_ 001 - https://www.media.poste.it/6a7ffb23-48ca-4da0-8809-5d99d243adb4/web/modello-cai-gtel con selettore_x000D_ 002 - https://www.media.poste.it/6a7ffb23-48ca-4da0-8809-5d99d243adb4/web/modello-cai-gtel con selettore_x000D_ _x000D_ Possibile Metodologia Risolutiva:_x000D_ 001 - Seleziona la lingua principale del PDF_x000D_ 002 - Correggere l'errore di sintassi nei metadati della lingua per consentire ai lettori di schermo di riconoscere correttamente la lingua._x000D_ _x000D_ Occorrenze rilevate: 2_x000D_ _x000D_ Link al dettaglio requisito WCAG: https://www.w3.org/WAI/WCAG21/quickref/_x000D_ | D12: 3 - Moderate | E12: (#PDF0019) | F12: 5971 | G12: 3 - Moderate | H12: D002 Modello CAI - GN | I12: 10.3.1.1 | J12: 001 - Impostazione della lingua predefinita utilizzando la voce /Lang nel catalogo documenti di un documento PDF - Impostazione della lingua predefinita utilizzando la voce /Lang nel catalogo documenti di un documento PDF (https://www.w3.org/WAI/WCAG22/Techniques/pdf/PDF16)_x000D_ 002 - I metadati della lingua del documento contengono un errore di sintassi - I metadati della lingua del documento contengono un errore di sintassi (https://www.w3.org/WAI/WCAG21/Techniques/html/H57) | K12: 001 - Seleziona la lingua principale del PDF_x000D_ 002 - Correggere l'errore di sintassi nei metadati della lingua per consentire ai lettori di schermo di riconoscere correttamente la lingua. | L12: 0 | M12: AP-00749 | N12: PK-02017
A13: D00210.3.1.2 | B13: =_xlfn.XLOOKUP(outTable[[#This Row],[ID Silk]],Tabella4[ID Silk],Tabella4[Titolo Defect],,0,1) -> Insurance Brocker - 10.3.1.2 Parti in lingua - D002 Modello CAI - GN: | C13: Insurance Brocker - 10.3.1.2 Parti in lingua - D002 Modello CAI - GN:: (#PDF0028)_x000D_ D002 Modello CAI - GN_x000D_ Requisito WCAG: 3.1.2_x000D_ Disabilità afflitte: Blind;Cognitive;Deafblind_x000D_ Impatto Utente: 2 - Serious_x000D_ _x000D_ Descrizione_x000D_ 001 - La lingua naturale per un oggetto di testo non può essere determinata. - La lingua naturale per un oggetto di testo non può essere determinata. (https://www.w3.org/TR/WCAG20-TECHS/PDF19.html)_x000D_ _x000D_ Esempio di violazione individuata sull'oggetto:_x000D_ 001 - https://www.media.poste.it/6a7ffb23-48ca-4da0-8809-5d99d243adb4/web/modello-cai-gtel con selettore_x000D_ _x000D_ Possibile Metodologia Risolutiva:_x000D_ 001 - In Adobe Acrobat Pro, vai su File > Proprietà > Avanzate e imposta la lingua predefinita del documento. Usa strumenti di verifica per controllare che tutti gli oggetti di testo ereditino correttamente questa impostazione._x000D_ _x000D_ Occorrenze rilevate: 1_x000D_ _x000D_ Link al dettaglio requisito WCAG: https://www.w3.org/WAI/WCAG21/quickref/_x000D_ | D13: 2 - Serious | E13: (#PDF0028) | F13: 5973 | G13: 2 - Serious | H13: D002 Modello CAI - GN | I13: 10.3.1.2 | J13: 001 - La lingua naturale per un oggetto di testo non può essere determinata. - La lingua naturale per un oggetto di testo non può essere determinata. (https://www.w3.org/TR/WCAG20-TECHS/PDF19.html) | K13: 001 - In Adobe Acrobat Pro, vai su File > Proprietà > Avanzate e imposta la lingua predefinita del documento. Usa strumenti di verifica per controllare che tutti gli oggetti di testo ereditino correttamente questa impostazione. | L13: 0 | M13: AP-00749 | N13: PK-02017
... A59: S0069.4.1.2 | B59: =_xlfn.XLOOKUP(outTable[[#This Row],[ID Silk]],Tabella4[ID Silk],Tabella4[Titolo Defect],,0,1) -> Insurance Brocker - 9.4.1.2 Nome, ruolo, valore - S006 L'azienda: | C59: Insurance Brocker - 9.4.1.2 Nome, ruolo, valore - S006 L'azienda:: (#TM0178)_x000D_ S006 L'azienda_x000D_ Requisito WCAG: 4.1.2_x000D_ Disabilità afflitte: Blind;Mobility_x000D_ Impatto Utente: 2 - Serious_x000D_ _x000D_ Descrizione_x000D_ 001 - I controlli interattivi non devono essere nidificati - Assicurarsi che i controlli interattivi non siano nidificati in quanto non vengono sempre annunciati dagli screen reader o possono causare problemi di messa a fuoco per le tecnologie assistive [Ulteriori informazioni] (https://dequeuniversity.com/rules/axe/4.8/nested-interactive?application=playwright)_x000D_ _x000D_ Esempio di violazione individuata sull'oggetto:_x000D_ 001 - https://posteinsurancebroker.poste.it/segnalazioni-anomalie/ <div class="panel-heading" role="tab" tabindex="0" id="heading-item-posteinsurancebrokerposteinsurancebroker-modulisegnalazioni-anomalie-accordion-faqchi-puo-inviare-una-segnalazione-0-0"> con selettore ["#heading-item-posteinsurancebrokerposteinsurancebroker-modulisegnalazioni-anomalie-accordion-faqchi-puo-inviare-una-segnalazione-0-0"]_x000D_ _x000D_ Possibile Metodologia Risolutiva:_x000D_ 001 - Evita di nidificare elementi interattivi (es. un pulsante all'interno di un link). Ristruttura il codice per garantire che ogni controllo interattivo sia indipendente e non sovrapposto ad altri, ad esempio utilizzando uno stile o un elemento contenitore non interattivo._x000D_ _x000D_ Occorrenze rilevate: 1_x000D_ _x000D_ Link al dettaglio requisito WCAG: https://www.w3.org/WAI/WCAG21/quickref/_x000D_ | D59: 2 - Serious | E59: (#TM0178) | F59: 5999 | G59: 2 - Serious | H59: S006 L'azienda | I59: 9.4.1.2 | J59: 001 - I controlli interattivi non devono essere nidificati - Assicurarsi che i controlli interattivi non siano nidificati in quanto non vengono sempre annunciati dagli screen reader o possono causare problemi di messa a fuoco per le tecnologie assistive [Ulteriori informazioni] (https://dequeuniversity.com/rules/axe/4.8/nested-interactive?application=playwright) | K59: 001 - Evita di nidificare elementi interattivi (es. un pulsante all'interno di un link). Ristruttura il codice per garantire che ogni controllo interattivo sia indipendente e non sovrapposto ad altri, ad esempio utilizzando uno stile o un elemento contenitore non interattivo. | L59: 0 | M59: AP-00749 | N59: PK-02017

Sheet Copertina
B2: Nome Servizio/Applicativo | C2: Insurance Brocker
B3: URL Sito | C3: https://posteinsurancebroker.poste.it/
B4: URL Log | C4: https://posteitaliane.sharepoint.com/:x:/r/teams/ACCESSIBILITRISULTATIVERIFICHETECNICHE-POSTEVITA/Shared%20Documents/POSTEVITA/POSTEINSURANCEBROKER/LOG/Log.xlsx?d=wf366087fe8434439bad12bec43ef8001&csf=1&web=1&e=uRH2su
B5: Pagine analizzate con tool automatici | C5: =COUNTA(Tabella1[Page ID])&" pagine" -> 14 pagine
C6: ="score medio Lighthouse: "&ROUND(AVERAGE(Tabella1[Score]),0)&"/100" -> score medio Lighthouse: 92/100
C7: =COUNTA(Tabella27[PDF ID])&" documenti PDF" -> 5 documenti PDF
C8: ="score medio MAUVE++: "&ROUND(AVERAGE(Tabella27[M - Score]),0)&"/100" -> score medio MAUVE++: 46/100
B9: Failure rilevate | C9: =COUNTA(Tabella4[Livello])&" failure univoche:" -> 483 failure univoche:
C10: ="A: "&COUNTIF(Tabella4[Livello],"A") -> A: 236
C11: ="AA: "&COUNTIF(Tabella4[Livello],"AA")+COUNTIF(Tabella399[Fail],"AA") -> AA: 247
C12: ="AAA: "&COUNTIF(Tabella4[Livello],"AAA")+COUNTIF(Tabella399[Fail],"AAA") -> AAA: 0
C13: ="Best Practice: "&COUNTIF(Tabella4[Livello],"BP")+COUNTIF(Tabella399[Fail],"BP") -> Best Practice: 0

Sheet Page Status_Summary
L1: Desktop | P1: Mobile
A2: Page ID | B2: URL | C2: Funzionalità | D2: Servizio | E2: Campione | F2: Nome del file | G2: Score | H2: Passed | I2: Not Passed | J2: Not Applicable | K2: Issue | L2: Desktop Score | M2: D-Passed | N2: D-Not Passed | O2: D-Not Applicable | P2: Mobile Score | Q2: M-Passed | R2: M-Not Passed | S2: M-Not Applicable
A3: #1 | B3: https://posteinsurancebroker.poste.it/ | C3: =_xlfn.XLOOKUP(Tabella1[[#This Row],[Servizio]],Tabella5[Area funzionale],Tabella5[Funzionalita],,0,1) -> F0001 Elenco offerte e servizi | D3: S001 Homepage | E3: Ok | G3: =AVERAGE(Tabella1[[#This Row],[Mobile Score]],Tabella1[[#This Row],[Desktop Score]]) -> 91.5 | H3: =AVERAGE(Tabella1[[#This Row],[M-Passed]],Tabella1[[#This Row],[D-Passed]]) -> 21 | I3: =AVERAGE(Tabella1[[#This Row],[M-Not Passed]],Tabella1[[#This Row],[D-Not Passed]]) -> 2 | J3: =AVERAGE(Tabella1[[#This Row],[M-Not Applicable]],Tabella1[[#This Row],[D-Not Applicable]]) -> 31 | K3: =COUNTIF(Tabella4[Page ID],Tabella1[[#This Row],[Page ID]]) -> 18 | L3: 91 | M3: 20 | N3: 2 | O3: 32 | P3: 92 | Q3: 22 | R3: 2 | S3: 30
A4: #2 | B4: https://posteinsurancebroker.poste.it/archivio/ | C4: =_xlfn.XLOOKUP(Tabella1[[#This Row],[Servizio]],Tabella5[Area funzionale],Tabella5[Funzionalita],,0,1) -> F0004 Assistenza Clienti | D4: S003 Assistenza | E4: Ok | G4: =AVERAGE(Tabella1[[#This Row],[Mobile Score]],Tabella1[[#This Row],[Desktop Score]]) -> 93 | H4: =AVERAGE(Tabella1[[#This Row],[M-Passed]],Tabella1[[#This Row],[D-Passed]]) -> 23 | I4: =AVERAGE(Tabella1[[#This Row],[M-Not Passed]],Tabella1[[#This Row],[D-Not Passed]]) -> 2 | J4: =AVERAGE(Tabella1[[#This Row],[M-Not Applicable]],Tabella1[[#This Row],[D-Not Applicable]]) -> 29 | K4: =COUNTIF(Tabella4[Page ID],Tabella1[[#This Row],[Page ID]]) -> 48 | L4: 93 | M4: 23 | N4: 2 | O4: 29 | P4: 93 | Q4: 23 | R4: 2 | S4: 29
A5: #3 | B5: https://posteinsurancebroker.poste.it/assistenza | C5: =_xlfn.XLOOKUP(Tabella1[[#This Row],[Servizio]],Tabella5[Area funzionale],Tabella5[Funzionalita],,0,1) -> F0004 Assistenza Clienti | D5: S003 Assistenza | E5: Ok | G5: =AVERAGE(Tabella1[[#This Row],[Mobile Score]],Tabella1[[#This Row],[Desktop Score]]) -> 92.5 | H5: =AVERAGE(Tabella1[[#This Row],[M-Passed]],Tabella1[[#This Row],[D-Passed]]) -> 21 | I5: =AVERAGE(Tabella1[[#This Row],[M-Not Passed]],Tabella1[[#This Row],[D-Not Passed]]) -> 1 | J5: =AVERAGE(Tabella1[[#This Row],[M-Not Applicable]],Tabella1[[#This Row],[D-Not Applicable]]) -> 32 | K5: =COUNTIF(Tabella4[Page ID],Tabella1[[#This Row],[Page ID]]) -> 11 | L5: 91 | M5: 19 | N5: 1 | O5: 34 | P5: 94 | Q5: 23 | R5: 1 | S5: 30
A6: #5 | B6: https://posteinsurancebroker.poste.it/chiamaci/ | C6: =_xlfn.XLOOKUP(Tabella1[[#This Row],[Servizio]],Tabella5[Area funzionale],Tabella5[Funzionalita],,0,1) -> F0004 Assistenza Clienti | D6: S003 Assistenza | E6: Ok | G6: =AVERAGE(Tabella1[[#This Row],[Mobile Score]],Tabella1[[#This Row],[Desktop Score]]) -> 92.5 | H6: =AVERAGE(Tabella1[[#This Row],[M-Passed]],Tabella1[[#This Row],[D-Passed]]) -> 21 | I6: =AVERAGE(Tabella1[[#This Row],[M-Not Passed]],Tabella1[[#This Row],[D-Not Passed]]) -> 1 | J6: =AVERAGE(Tabella1[[#This Row],[M-Not Applicable]],Tabella1[[#This Row],[D-Not Applicable]]) -> 32 | K6: =COUNTIF(Tabella4[Page ID],Tabella1[[#This Row],[Page ID]]) -> 8 | L6: 91 | M6: 19 | N6: 1 | O6: 34 | P6: 94 | Q6: 23 | R6: 1 | S6: 30
A7: #6 | B7: https://posteinsurancebroker.poste.it/cookie-policy | C7: =_xlfn.XLOOKUP(Tabella1[[#This Row],[Servizio]],Tabella5[Area funzionale],Tabella5[Funzionalita],,0,1) -> F0011 Documentazione Privacy Policy | D7: S005 Privacy Policy | G7: =AVERAGE(Tabella1[[#This Row],[Mobile Score]],Tabella1[[#This Row],[Desktop Score]]) -> 94 | H7: =AVERAGE(Tabella1[[#This Row],[M-Passed]],Tabella1[[#This Row],[D-Passed]]) -> 23 | I7: =AVERAGE(Tabella1[[#This Row],[M-Not Passed]],Tabella1[[#This Row],[D-Not Passed]]) -> 1 | J7: =AVERAGE(Tabella1[[#This Row],[M-Not Applicable]],Tabella1[[#This Row],[D-Not Applicable]]) -> 30 | K7: =COUNTIF(Tabella4[Page ID],Tabella1[[#This Row],[Page ID]]) -> 2 | L7: 94 | M7: 23 | N7: 1 | O7: 30 | P7: 94 | Q7: 23 | R7: 1 | S7: 30
A8: #7 | B8: https://posteinsurancebroker.poste.it/dichiarazione-accessibilita/ | C8: =_xlfn.XLOOKUP(Tabella1[[#This Row],[Servizio]],Tabella5[Area funzionale],Tabella5[Funzionalita],,0,1) -> F0010 Dichiarazione di Accessibilità | D8: S004 Accessibilità | G8: =AVERAGE(Tabella1[[#This Row],[Mobile Score]],Tabella1[[#This Row],[Desktop Score]]) -> 92.5 | H8: =AVERAGE(Tabella1[[#This Row],[M-Passed]],Tabella1[[#This Row],[D-Passed]]) -> 21 | I8: =AVERAGE(Tabella1[[#This Row],[M-Not Passed]],Tabella1[[#This Row],[D-Not Passed]]) -> 1 | J8: =AVERAGE(Tabella1[[#This Row],[M-Not Applicable]],Tabella1[[#This Row],[D-Not Applicable]]) -> 32 | K8: =COUNTIF(Tabella4[Page ID],Tabella1[[#This Row],[Page ID]]) -> 2 | L8: 91 | M8: 19 | N8: 1 | O8: 34 | P8: 94 | Q8: 23 | R8: 1 | S8: 30
A9: #8 | B9: https://posteinsurancebroker.poste.it/faq-poste-guidare-sicuri/ | C9: =_xlfn.XLOOKUP(Tabella1[[#This Row],[Servizio]],Tabella5[Area funzionale],Tabella5[Funzionalita],,0,1) -> F0002 Descrizione Polizza | D9: S002 Poste Guidare Sicuri | E9: Ok | G9: =AVERAGE(Tabella1[[#This Row],[Mobile Score]],Tabella1[[#This Row],[Desktop Score]]) -> 94 | H9: =AVERAGE(Tabella1[[#This Row],[M-Passed]],Tabella1[[#This Row],[D-Passed]]) -> 23 | I9: =AVERAGE(Tabella1[[#This Row],[M-Not Passed]],Tabella1[[#This Row],[D-Not Passed]]) -> 1 | J9: =AVERAGE(Tabella1[[#This Row],[M-Not Applicable]],Tabella1[[#This Row],[D-Not Applicable]]) -> 30 | K9: =COUNTIF(Tabella4[Page ID],Tabella1[[#This Row],[Page ID]]) -> 166 | L9: 94 | M9: 23 | N9: 1 | O9: 30 | P9: 94 | Q9: 23 | R9: 1 | S9: 30
A10: #9 | B10: https://posteinsurancebroker.poste.it/fastquote/index.html | C10: =_xlfn.XLOOKUP(Tabella1[[#This Row],[Servizio]],Tabella5[Area funzionale],Tabella5[Funzionalita],,0,1) -> F0002 Descrizione Polizza | D10: S002 Poste Guidare Sicuri | E10: Ok | G10: =AVERAGE(Tabella1[[#This Row],[Mobile Score]],Tabella1[[#This Row],[Desktop Score]]) -> 87 | H10: =AVERAGE(Tabella1[[#This Row],[M-Passed]],Tabella1[[#This Row],[D-Passed]]) -> 23 | I10: =AVERAGE(Tabella1[[#This Row],[M-Not Passed]],Tabella1[[#This Row],[D-Not Passed]]) -> 2 | J10: =AVERAGE(Tabella1[[#This Row],[M-Not Applicable]],Tabella1[[#This Row],[D-Not Applicable]]) -> 29 | K10: =COUNTIF(Tabella4[Page ID],Tabella1[[#This Row],[Page ID]]) -> 17 | L10: 87 | M10: 23 | N10: 2 | O10: 29 | P10: 87 | Q10: 23 | R10: 2 | S10: 29
A11: #10 | B11: https://posteinsurancebroker.poste.it/glossario-assicurativo/ | C11: =_xlfn.XLOOKUP(Tabella1[[#This Row],[Servizio]],Tabella5[Area funzionale],Tabella5[Funzionalita],,0,1) -> F0004 Assistenza Clienti | D11: S003 Assistenza | E11: Ok | G11: =AVERAGE(Tabella1[[#This Row],[Mobile Score]],Tabella1[[#This Row],[Desktop Score]]) -> 87 | H11: =AVERAGE(Tabella1[[#This Row],[M-Passed]],Tabella1[[#This Row],[D-Passed]]) -> 23 | I11: =AVERAGE(Tabella1[[#This Row],[M-Not Passed]],Tabella1[[#This Row],[D-Not Passed]]) -> 2 | J11: =AVERAGE(Tabella1[[#This Row],[M-Not Applicable]],Tabella1[[#This Row],[D-Not Applicable]]) -> 29 | K11: =COUNTIF(Tabella4[Page ID],Tabella1[[#This Row],[Page ID]]) -> 7 | L11: 87 | M11: 23 | N11: 2 | O11: 29 | P11: 87 | Q11: 23 | R11: 2 | S11: 29
A12: #11 | B12: https://posteinsurancebroker.poste.it/poste-guidare-sicuri/ | C12: =_xlfn.XLOOKUP(Tabella1[[#This Row],[Servizio]],Tabella5[Area funzionale],Tabella5[Funzionalita],,0,1) -> F0002 Descrizione Polizza | D12: S002 Poste Guidare Sicuri | E12: Ok | G12: =AVERAGE(Tabella1[[#This Row],[Mobile Score]],Tabella1[[#This Row],[Desktop Score]]) -> 94 | H12: =AVERAGE(Tabella1[[#This Row],[M-Passed]],Tabella1[[#This Row],[D-Passed]]) -> 23 | I12: =AVERAGE(Tabella1[[#This Row],[M-Not Passed]],Tabella1[[#This Row],[D-Not Passed]]) -> 1 | J12: =AVERAGE(Tabella1[[#This Row],[M-Not Applicable]],Tabella1[[#This Row],[D-Not Applicable]]) -> 30 | K12: =COUNTIF(Tabella4[Page ID],Tabella1[[#This Row],[Page ID]]) -> 52 | L12: 94 | M12: 23 | N12: 1 | O12: 30 | P12: 94 | Q12: 23 | R12: 1 | S12: 30
A13: #12 | B13: https://posteinsurancebroker.poste.it/privacy-policy | C13: =_xlfn.XLOOKUP(Tabella1[[#This Row],[Servizio]],Tabella5[Area funzionale],Tabella5[Funzionalita],,0,1) -> F0011 Documentazione Privacy Policy | D13: S005 Privacy Policy | E13: Ok | G13: =AVERAGE(Tabella1[[#This Row],[Mobile Score]],Tabella1[[#This Row],[Desktop Score]]) -> 94 | H13: =AVERAGE(Tabella1[[#This Row],[M-Passed]],Tabella1[[#This Row],[D-Passed]]) -> 23 | I13: =AVERAGE(Tabella1[[#This Row],[M-Not Passed]],Tabella1[[#This Row],[D-Not Passed]]) -> 1 | J13: =AVERAGE(Tabella1[[#This Row],[M-Not Applicable]],Tabella1[[#This Row],[D-Not Applicable]]) -> 30 | K13: =COUNTIF(Tabella4[Page ID],Tabella1[[#This Row],[Page ID]]) -> 26 | L13: 94 | M13: 23 | N13: 1 | O13: 30 | P13: 94 | Q13: 23 | R13: 1 | S13: 30
A14: #13 | B14: https://posteinsurancebroker.poste.it/reclami/ | C14: =_xlfn.XLOOKUP(Tabella1[[#This Row],[Servizio]],Tabella5[Area funzionale],Tabella5[Funzionalita],,0,1) -> F0004 Assistenza Clienti | D14: S003 Assistenza | E14: Ok | G14: =AVERAGE(Tabella1[[#This Row],[Mobile Score]],Tabella1[[#This Row],[Desktop Score]]) -> 92.5 | H14: =AVERAGE(Tabella1[[#This Row],[M-Passed]],Tabella1[[#This Row],[D-Passed]]) -> 21 | I14: =AVERAGE(Tabella1[[#This Row],[M-Not Passed]],Tabella1[[#This Row],[D-Not Passed]]) -> 1 | J14: =AVERAGE(Tabella1[[#This Row],[M-Not Applicable]],Tabella1[[#This Row],[D-Not Applicable]]) -> 32 | K14: =COUNTIF(Tabella4[Page ID],Tabella1[[#This Row],[Page ID]]) -> 15 | L14: 91 | M14: 19 | N14: 1 | O14: 34 | P14: 94 | Q14: 23 | R14: 1 | S14: 30
A15: #14 | B15: https://posteinsurancebroker.poste.it/segnalazioni-anomalie/ | C15: =_xlfn.XLOOKUP(Tabella1[[#This Row],[Servizio]],Tabella5[Area funzionale],Tabella5[Funzionalita],,0,1) -> F0012 https://posteinsurancebroker.poste.it/segnalazioni-anomalie/ | D15: S006 L'azienda | E15: Ok | G15: =AVERAGE(Tabella1[[#This Row],[Mobile Score]],Tabella1[[#This Row],[Desktop Score]]) -> 94 | H15: =AVERAGE(Tabella1[[#This Row],[M-Passed]],Tabella1[[#This Row],[D-Passed]]) -> 23 | I15: =AVERAGE(Tabella1[[#This Row],[M-Not Passed]],Tabella1[[#This Row],[D-Not Passed]]) -> 1 | J15: =AVERAGE(Tabella1[[#This Row],[M-Not Applicable]],Tabella1[[#This Row],[D-Not Applicable]]) -> 30 | K15: =COUNTIF(Tabella4[Page ID],Tabella1[[#This Row],[Page ID]]) -> 39 | L15: 94 | M15: 23 | N15: 1 | O15: 30 | P15: 94 | Q15: 23 | R15: 1 | S15: 30
A16: #15 | B16: https://posteinsurancebroker.poste.it/sinistri/ | C16: =_xlfn.XLOOKUP(Tabella1[[#This Row],[Servizio]],Tabella5[Area funzionale],Tabella5[Funzionalita],,0,1) -> F0004 Assistenza Clienti | D16: S003 Assistenza | E16: Ok | G16: =AVERAGE(Tabella1[[#This Row],[Mobile Score]],Tabella1[[#This Row],[Desktop Score]]) -> 92.5 | H16: =AVERAGE(Tabella1[[#This Row],[M-Passed]],Tabella1[[#This Row],[D-Passed]]) -> 21 | I16: =AVERAGE(Tabella1[[#This Row],[M-Not Passed]],Tabella1[[#This Row],[D-Not Passed]]) -> 1 | J16: =AVERAGE(Tabella1[[#This Row],[M-Not Applicable]],Tabella1[[#This Row],[D-Not Applicable]]) -> 32 | K16: =COUNTIF(Tabella4[Page ID],Tabella1[[#This Row],[Page ID]]) -> 14 | L16: 91 | M16: 19 | N16: 1 | O16: 34 | P16: 94 | Q16: 23 | R16: 1 | S16: 30

Sheet Pivot
A3: Servizio Digitale | B3: Count of ID Silk
A4: 10.1.1.1 | B4: 11
A5: 10.1.3.1 | B5: 44 | E5: =_xlfn.TEXTJOIN(",",TRUE,D:D) -> 2616,2629,2640,2654,2669,2676,2681,2686,2699,2704,2715,2726
A6: 10.1.4.1 | B6: 1
A7: 10.1.4.3 | B7: 4
A8: 10.2.4.2 | B8: 43 | E8: \
A9: 10.3.1.1 | B9: 17
A10: 10.4.1.1 | B10: 1
A11: 12.2.2 | B11: 1
A12: 12.2.3 | B12: 1
A13: 9.1.1.1 | B13: 19
A14: 9.1.2.1 | B14: 6
A15: 9.1.2.2 | B15: 2
A16: 9.1.3.1 | B16: 19
A17: 9.1.3.2 | B17: 3
A18: 9.1.4.1 | B18: 4
A19: 9.1.4.3 | B19: 19
A20: 9.1.4.5 | B20: 2
... A25: 9.3.1.1 | B25: 1
A26: 2653 | B26: 1
A27: 9.3.3.2 | B27: 2
A28: 2667 | B28: 1
A29: 2698 | B29: 1
A30: 9.4.1.1 | B30: 1
A31: 2725 | B31: 1
A32: 9.4.1.2 | B32: 12
A33: 2616 | B33: 1 | D33: 2616
A34: 2629 | B34: 1 | D34: 2629
A35: 2640 | B35: 1 | D35: 2640
A36: 2654 | B36: 1 | D36: 2654
A37: 2669 | B37: 1 | D37: 2669
A38: 2676 | B38: 1 | D38: 2676
A39: 2681 | B39: 1 | D39: 2681
A40: 2686 | B40: 1 | D40: 2686
A41: 2699 | B41: 1 | D41: 2699
A42: 2704 | B42: 1 | D42: 2704
A43: 2715 | B43: 1 | D43: 2715
A44: 2726 | B44: 1 | D44: 2726
A45: Totali | B45: 244

Sheet Not Passed
A1: ID Silk | B1: subID | C1: #ID | D1: ID defectXsilk | E1: Componente | F1: Livello | G1: Criterio | H1: UNI CEI EN 301549 | I1: User Impact | J1: Disabilities | K1: Title | L1: Titolo | M1: Descrizione | N1: Rejected Element | O1: Detail | P1: URL | Q1: Nome del file | R1: Page ID | S1: Tool | T1: ID | U1: ItemsNodeLabel | V1: ItemsExplanation | W1: Soluzione note aggiuntive | X1: Detail univoco | Y1: Rejected Element Univoco | Z1: Diffusione | AA1: Servizio | AB1: Share URL | AC1: Severity | AD1: Titolo Defect | AE1: Description Defect | AF1: Caricato su Silk
A2: =MID(Tabella4[[#This Row],[Servizio]],1,4)&Tabella4[[#This Row],[UNI CEI EN 301549]] -> S0019.4.1.1 | B2: =Tabella4[[#This Row],[ID Silk]]&"_1" -> S0019.4.1.1_1 | C2: D0001 | D2: ="(#"&Tabella4[[#This Row],['#ID]]&")" -> (#D0001) | E2: =IF(MID(Tabella4[[#This Row],['#ID]],1,1)="M","Mobile",IF(MID(Tabella4[[#This Row],['#ID]],1,1)="D","Desktop",IF(MID(Tabella4[[#This Row],['#ID]],1,2)="TM","Manuale","Documenti"))) -> Desktop | F2: A | G2: 4.1.1 | H2: =IF(Tabella4[[#This Row],[Componente]]="Documenti","10.","9.")&Tabella4[[#This Row],[Criterio]] -> 9.4.1.1 | I2: 1 - Critical | J2: Blind;Deafblind | K2: ARIA IDs are not unique | L2: Gli ID ARIA non sono univoci | M2: Il valore di un ID ARIA deve essere univoco per evitare che altre istanze vengano trascurate dalle tecnologie assistive. [Ulteriori informazioni] (https://web.dev/duplicate-id-aria/) | N2: div.side-offcanvas-content-wrap > div.row > div.col-sm-12 > p#offcanvas-panel-desc-00_sites | O2: <p id=\"offcanvas-panel-desc-00_sites\" class=\"sr-only\"> | P2: https://posteinsurancebroker.poste.it/ | R2: =IF(Tabella4[[#This Row],[Componente]]="Documenti",_xlfn.XLOOKUP(Tabella4[[#This Row],[URL]],Tabella27[URL],Tabella27[PDF ID],,0),_xlfn.XLOOKUP(Tabella4[[#This Row],[URL]],Tabella1[URL],Tabella1[Page ID],,0)) -> #1 | S2: lighthouse | T2: duplicate-id-aria | U2: div.side-offcanvas-content-wrap > div.row > div.col-sm-12 > p#offcanvas-panel-desc-00_sites | V2: Fix any of the following:\n Document has multiple elements referenced with ARIA with the same id attribute: offcanvas-panel-desc-00_sites | W2: Cambia il valore dell'ID usato piu di una volta, per essere sicuro che sia univoco | X2: =IFERROR(IF(Tabella4[[#This Row],[Tool]]="lighthouse",Tabella4[[#This Row],[Detail]],MID(Tabella4[[#This Row],[Detail]],1,FIND(">",Tabella4[[#This Row],[Detail]]))),Tabella4[[#This Row],[Detail]]) -> <p id=\"offcanvas-panel-desc-00_sites\" class=\"sr-only\"> | Y2: =SUBSTITUTE(IF(Tabella4[[#This Row],[Tool]]="axe-core",MID(Tabella4[[#This Row],[Rejected Element]],3,LEN(Tabella4[[#This Row],[Rejected Element]])-4),Tabella4[[#This Row],[Rejected Element]]),"\","") -> div.side-offcanvas-content-wrap > div.row > div.col-sm-12 > p#offcanvas-panel-desc-00_sites | Z2: =COUNTIFS(Tabella4[Detail univoco],Tabella4[[#This Row],[Detail univoco]],Tabella4[Rejected Element Univoco],Tabella4[[#This Row],[Rejected Element Univoco]],Tabella4[ItemsNodeLabel],Tabella4[[#This Row],[ItemsNodeLabel]]) -> 15 | AA2: =IF(Tabella4[[#This Row],[Componente]]="Documenti",VLOOKUP(Tabella4[[#This Row],[URL]],Tabella27[[URL]:[Servizio]],4,FALSE),VLOOKUP(Tabella4[[#This Row],[Page ID]],Tabella1[[Page ID]:[Servizio]],4,FALSE)) -> S001 Homepage | AC2: =Tabella4[[#This Row],[User Impact]] -> 1 - Critical | AD2: =Copertina!C$2&" - "&Tabella4[[#This Row],[UNI CEI EN 301549]]&" "&VLOOKUP(Tabella4[[#This Row],[Criterio]],Tabella5[[ID]:[Criterio di successo]],2,FALSE)&" - "&Tabella4[[#This Row],[Servizio]]&":" -> Insurance Brocker - 9.4.1.1 Analisi sintattica (parsing) - S001 Homepage: | AE2: =_xlfn.CONCAT(Tabella4[[#This Row],[Titolo Defect]]," ",Tabella4[[#This Row],[ID defectXsilk]],CHAR(10),Tabella4[[#This Row],[Servizio]],CHAR(10),_xlfn.CONCAT("Requisito: WCAG ", Tabella4[[#This Row],[Criterio]],CHAR(10), "Disabilità afflitte: ",Tabella4[[#This Row],[Disabilities]],CHAR(10), "Impatto Utente: ",Tabella4[[#This Row],[User Impact]],CHAR(10),CHAR(10), "Descrizione: ",Tabella4[[#This Row],[Titolo]]," - ",Tabella4[[#This Row],[Descrizione]],CHAR(10),CHAR(10), "Esempio di violazione individuata sull'oggetto: ",CHAR(10),Tabella4[[#This Row],[URL]]," - ",Tabella4[[#This Row],[Detail]]," con selettore: ",CHAR(10),Tabella4[[#This Row],[Rejected Element]],CHAR(10),CHAR(10), "Dettaglio + screenshot (accedere con le seguenti credenziali: user, axeposte@gmail.com; password, Poste2024!): ",Tabella4[[#This Row],[Share URL]],CHAR(10) ),CHAR(10),"Possibile metodologia risolutiva:"&CHAR(10),Tabella4[[#This Row],[Soluzione note aggiuntive]],CHAR(10),CHAR(10),"File di log (occorrenze rilevate: "&COUNTIF(Tabella4[ID Silk],Tabella4[[#This Row],[ID Silk]])&"): https://posteitaliane.sharepoint.com/:x:/r/teams/ACCESSIBILITRISULTATIVERIFICHETECNICHE-PORTALEIMMIGRAZIONE/Shared%20Documents/PORTALE%20IMMIGRAZIONE/LOG/Log_2411.xlsx?d=wce770a595441461abc11f2c139111c73&csf=1&web=1&e=tpdJfo",CHAR(10),CHAR(10),"Link al dettaglio requisito WCAG: ",IFERROR(VLOOKUP(Tabella4[[#This Row],[UNI CEI EN 301549]],'Dati input'!E$1:G$27,3,FALSE),"")) -> Insurance Brocker - 9.4.1.1 Analisi sintattica (parsing) - S001 Homepage: (#D0001) S001 Homepage Requisito: WCAG 4.1.1 Disabilità afflitte: Blind;Deafblind Impatto Utente: 1 - Critical Descrizione: Gli ID ARIA non sono univoci - Il valore di un ID ARIA deve essere univoco per evitare che altre istanze vengano trascurate dalle tecnologie assistive. [Ulteriori informazioni] (https://web.dev/duplicate-id-aria/) Esempio di violazione individuata sull'oggetto: https://posteinsurancebroker.poste.it/ - <p id=\"offcanvas-panel-desc-00_sites\" class=\"sr-only\"> con selettore: div.side-offcanvas-content-wrap > div.row > div.col-sm-12 > p#offcanvas-panel-desc-00_sites Dettaglio + screenshot (accedere con le seguenti credenziali: user, axeposte@gmail.com; password, Poste2024!): Possibile metodologia risolutiva: Cambia il valore dell'ID usato piu di una volta, per essere sicuro che sia univoco File di log (occorrenze rilevate: 2): https://posteitaliane.sharepoint.com/:x:/r/teams/ACCESSIBILITRISULTATIVERIFICHETECNICHE-PORTALEIMMIGRAZIONE/Shared%20Documents/PORTALE%20IMMIGRAZIONE/LOG/Log_2411.xlsx?d=wce770a595441461abc11f2c139111c73&csf=1&web=1&e=tpdJfo Link al dettaglio requisito WCAG: | AF2: =_xlfn.XLOOKUP(Tabella4[[#This Row],[ID Silk]],outTable[ID Silk],outTable[Numero ticket ],,0,1) -> 6007
