Workbook

Sheet Copertina
B2: Nome Servizio/Applicativo | C2: App IndaBox Android
B3: URL Playstore | C3: https://play.google.com/store/search?q=indabox&c=apps&hl=it
B4: URL Log | C4: https://posteitaliane.sharepoint.com/:x:/r/teams/ACCESSIBILITRISULTATIVERIFICHETECNICHE-DIGITAL_APP/Shared%20Documents/DIGITAL_APP/INDABOX/LOG/Log%20Android.xlsx?d=wab03158ff1604225bf629c54ace00e42&csf=1&web=1&e=L4CRfw
B5: Pagine analizzate con tool automatici | C5: =COUNTA(Tabella1[Page ID])&" pagine" -> 48 pagine
B7: Failure rilevate | C7: =COUNTA(Tabella4[Livello])&" failure univoche:" -> 2037 failure univoche:
C8: ="A: "&COUNTIF(Tabella4[Livello],"A") -> A: 938
C9: ="AA: "&COUNTIF(Tabella4[Livello],"AA") -> AA: 893
C10: ="AAA: "&COUNTIF(Tabella4[Livello],"AAA") -> AAA: 206
C11: ="Best Practice: "&COUNTIF(Tabella4[Livello],"BP") -> Best Practice: 0

Sheet Page Status_Summary
A1: Page ID | B1: Pagina | C1: Servizio | D1: Campione | E1: A | F1: AA | G1: Issue
A2: #1 | B2: Home password dimenticata.txt | C2: S002 Registrazione | E2: =COUNTIFS(Tabella4[Livello],"A",Tabella4[Pagina],Tabella1[[#This Row],[Pagina]]) -> 15 | F2: =COUNTIFS(Tabella4[Livello],"AA",Tabella4[Pagina],Tabella1[[#This Row],[Pagina]]) -> 14 | G2: =COUNTIF(Tabella4[Page ID],Tabella1[[#This Row],[Page ID]]) -> 35
A3: #2 | B3: Home prezzi.txt | C3: S012 Prezzi | E3: =COUNTIFS(Tabella4[Livello],"A",Tabella4[Pagina],Tabella1[[#This Row],[Pagina]]) -> 15 | F3: =COUNTIFS(Tabella4[Livello],"AA",Tabella4[Pagina],Tabella1[[#This Row],[Pagina]]) -> 13 | G3: =COUNTIF(Tabella4[Page ID],Tabella1[[#This Row],[Page ID]]) -> 34
A4: #3 | B4: Home pubblica accessibilit .txt | C4: S015 Accessibilità | E4: =COUNTIFS(Tabella4[Livello],"A",Tabella4[Pagina],Tabella1[[#This Row],[Pagina]]) -> 21 | F4: =COUNTIFS(Tabella4[Livello],"AA",Tabella4[Pagina],Tabella1[[#This Row],[Pagina]]) -> 18 | G4: =COUNTIF(Tabella4[Page ID],Tabella1[[#This Row],[Page ID]]) -> 46
A5: #4 | B5: Home pubblica ritira.txt | C5: S003 Ritira (IndaBox Ritiro Pacchi) | E5: =COUNTIFS(Tabella4[Livello],"A",Tabella4[Pagina],Tabella1[[#This Row],[Pagina]]) -> 17 | F5: =COUNTIFS(Tabella4[Livello],"AA",Tabella4[Pagina],Tabella1[[#This Row],[Pagina]]) -> 15 | G5: =COUNTIF(Tabella4[Page ID],Tabella1[[#This Row],[Page ID]]) -> 38
A6: #5 | B6: Home pubblica.txt | C6: S001 Accedi | E6: =COUNTIFS(Tabella4[Livello],"A",Tabella4[Pagina],Tabella1[[#This Row],[Pagina]]) -> 29 | F6: =COUNTIFS(Tabella4[Livello],"AA",Tabella4[Pagina],Tabella1[[#This Row],[Pagina]]) -> 24 | G6: =COUNTIF(Tabella4[Page ID],Tabella1[[#This Row],[Page ID]]) -> 64
A7: #6 | B7: home pubblico hai una attivit .txt | C7: S001 Accedi | E7: =COUNTIFS(Tabella4[Livello],"A",Tabella4[Pagina],Tabella1[[#This Row],[Pagina]]) -> 25 | F7: =COUNTIFS(Tabella4[Livello],"AA",Tabella4[Pagina],Tabella1[[#This Row],[Pagina]]) -> 21 | G7: =COUNTIF(Tabella4[Page ID],Tabella1[[#This Row],[Page ID]]) -> 52
A8: #7 | B8: Privata acquista crediti.txt | C8: S007 Crediti Ritiro | E8: =COUNTIFS(Tabella4[Livello],"A",Tabella4[Pagina],Tabella1[[#This Row],[Pagina]]) -> 11 | F8: =COUNTIFS(Tabella4[Livello],"AA",Tabella4[Pagina],Tabella1[[#This Row],[Pagina]]) -> 10 | G8: =COUNTIF(Tabella4[Page ID],Tabella1[[#This Row],[Page ID]]) -> 21
A9: #8 | B9: Privata Azgomme.txt | C9: S004 Spedisci (IndaBox Spedizione Pacchi) | E9: =COUNTIFS(Tabella4[Livello],"A",Tabella4[Pagina],Tabella1[[#This Row],[Pagina]]) -> 0 | F9: =COUNTIFS(Tabella4[Livello],"AA",Tabella4[Pagina],Tabella1[[#This Row],[Pagina]]) -> 57 | G9: =COUNTIF(Tabella4[Page ID],Tabella1[[#This Row],[Page ID]]) -> 57
A10: #9 | B10: Privata bonus.txt | C10: S008 Bonus | E10: =COUNTIFS(Tabella4[Livello],"A",Tabella4[Pagina],Tabella1[[#This Row],[Pagina]]) -> 10 | F10: =COUNTIFS(Tabella4[Livello],"AA",Tabella4[Pagina],Tabella1[[#This Row],[Pagina]]) -> 8 | G10: =COUNTIF(Tabella4[Page ID],Tabella1[[#This Row],[Page ID]]) -> 22
A11: #10 | B11: Privata crediti.txt | C11: S007 Crediti Ritiro | E11: =COUNTIFS(Tabella4[Livello],"A",Tabella4[Pagina],Tabella1[[#This Row],[Pagina]]) -> 20 | F11: =COUNTIFS(Tabella4[Livello],"AA",Tabella4[Pagina],Tabella1[[#This Row],[Pagina]]) -> 7 | G11: =COUNTIF(Tabella4[Page ID],Tabella1[[#This Row],[Page ID]]) -> 29
A12: #11 | B12: Privata Dottor ink.txt | C12: S004 Spedisci (IndaBox Spedizione Pacchi) | E12: =COUNTIFS(Tabella4[Livello],"A",Tabella4[Pagina],Tabella1[[#This Row],[Pagina]]) -> 37 | F12: =COUNTIFS(Tabella4[Livello],"AA",Tabella4[Pagina],Tabella1[[#This Row],[Pagina]]) -> 43 | G12: =COUNTIF(Tabella4[Page ID],Tabella1[[#This Row],[Page ID]]) -> 80
A13: #12 | B13: Privata faq.txt | C13: S009 FAQ | E13: =COUNTIFS(Tabella4[Livello],"A",Tabella4[Pagina],Tabella1[[#This Row],[Pagina]]) -> 36 | F13: =COUNTIFS(Tabella4[Livello],"AA",Tabella4[Pagina],Tabella1[[#This Row],[Pagina]]) -> 42 | G13: =COUNTIF(Tabella4[Page ID],Tabella1[[#This Row],[Page ID]]) -> 91
... A49: #48 | B49: Pubblico Domande frequenti - Video.txt | C49: V001 Video tutorial | E49: =COUNTIFS(Tabella4[Livello],"A",Tabella4[Pagina],Tabella1[[#This Row],[Pagina]]) -> 1 | F49: =COUNTIFS(Tabella4[Livello],"AA",Tabella4[Pagina],Tabella1[[#This Row],[Pagina]]) -> 0 | G49: =COUNTIF(Tabella4[Page ID],Tabella1[[#This Row],[Page ID]]) -> 1

Sheet Foglio1
A3: Etichette di riga
A4: 10.1.2.2
A5: 11.1.1.1.1
A6: 11.1.3.1.1
A7: 11.1.3.2.1
A8: 11.1.3.4.1
A9: 11.1.4.3.1
A10: 11.1.4.5.1
A11: 11.2.5.3.1
A12: 11.4.1.2.1
A13: Totale complessivo

Sheet load to silk
A1: ID Silk | B1: Titolo | C1: Descrizione | D1: Severity | E1: Identificativo in relazione | F1: Numero ticket | G1: Priorità | H1: Servizio digitale / pagina | I1: Requisito (criterio) violato | J1: Errore | K1: Soluzione | L1: Link screenshot / video | M1: AP | N1: PK
A2: 11.1.3.1.1S001 Accedi | B2: =_xlfn.XLOOKUP(outTable[[#This Row],[ID Silk]],Tabella4[ID Silk],Tabella4[Titolo Defect],,0,1) -> APP INDABOX ANDROID - 11.1.3.1.1 Informazioni e correlazioni - S001 Accedi | C2: APP INDABOX ANDROID - 11.1.3.1.1 Informazioni e correlazioni - S001 Accedi: (#MAD009)_x000D_ S001 Accedi_x000D_ Requisito WCAG: 1.3.1_x000D_ Disabilità afflitte: Blind;Low Vision; Cognitive_x000D_ Impatto Utente: 2 - Serious_x000D_ _x000D_ Descrizione_x000D_ 001 - Elementi irrilevanti - VoiceOver legge elementi irrilevanti(https://www.w3.org/WAI/WCAG22/Understanding/info-and-relationships.html)_x000D_ _x000D_ Esempio di violazione individuata sull'oggetto:_x000D_ 001 - dopo la lettura del link "accessibilità" legge un elemento nascosto con selettore_x000D_ _x000D_ Possibile Metodologia Risolutiva:_x000D_ 001 - Impostare l'attributo "Aria-hidden" a true per nascondere un elemnto al VoiceOver_x000D_ _x000D_ Occorrenze rilevate: 1_x000D_ _x000D_ Link al dettaglio requisito WCAG: https://www.w3.org/WAI/WCAG21/quickref/_x000D_ | D2: 2 - Serious | E2: (#MAD009) | G2: 2 - Serious | H2: S001 Accedi | I2: 11.1.3.1.1 | J2: 001 - Elementi irrilevanti - VoiceOver legge elementi irrilevanti(https://www.w3.org/WAI/WCAG22/Understanding/info-and-relationships.html) | K2: 001 - Impostare l'attributo "Aria-hidden" a true per nascondere un elemnto al VoiceOver | L2: 0
A3: 11.1.3.2.1S001 Accedi | B3: =_xlfn.XLOOKUP(outTable[[#This Row],[ID Silk]],Tabella4[ID Silk],Tabella4[Titolo Defect],,0,1) -> APP INDABOX ANDROID - 11.1.3.2.1 Sequenza significativa - S001 Accedi | C3: APP INDABOX ANDROID - 11.1.3.2.1 Sequenza significativa - S001 Accedi: (#AAD717)_x000D_ S001 Accedi_x000D_ Requisito WCAG: 1.3.2_x000D_ Disabilità afflitte: Blind;Cognitive;Low Vision;Mobility_x000D_ Impatto Utente: 1 - Critical_x000D_ _x000D_ Descrizione_x000D_ 001 - FocusableText - Le visualizzazioni contenenti testo devono essere attivabili per le tecnologie per l'accesso facilitato, ad esempio TalkBack. [Per saperne di più] (https://docs.deque.com/devtools-mobile/2024.2.14/en/android-focusable-text)_x000D_ _x000D_ Esempio di violazione individuata sull'oggetto:_x000D_ 001 - con selettore No ID Available_x000D_ _x000D_ Dettaglio + screenshot (accedere con le seguenti credenziali: user, axeposte@gmail.com; password, Poste2024!)_x000D_ 001 - https://axe-mobile.deque.com/scan?userId=747da6b3-5f03-493b-bc9b-3a10276b7d6b&packageName=com.android.chrome&resultId=01987498-f715-719a-bc64-9e610b8007d0_x000D_ _x000D_ Possibile Metodologia Risolutiva:_x000D_ 001 - Rimuovi android:focusable="true" dal testo statico non interattivo._x000D_ _x000D_ Occorrenze rilevate: 1_x000D_ _x000D_ Link al dettaglio requisito WCAG: https://www.w3.org/WAI/WCAG21/quickref/_x000D_ | D3: 1 - Critical | E3: (#AAD717) | G3: 1 - Critical | H3: S001 Accedi | I3: 11.1.3.2.1 | J3: 001 - FocusableText - Le visualizzazioni contenenti testo devono essere attivabili per le tecnologie per l'accesso facilitato, ad esempio TalkBack. [Per saperne di più] (https://docs.deque.com/devtools-mobile/2024.2.14/en/android-focusable-text) | K3: 001 - Rimuovi android:focusable="true" dal testo statico non interattivo. | L3: 001 - https://axe-mobile.deque.com/scan?userId=747da6b3-5f03-493b-bc9b-3a10276b7d6b&packageName=com.android.chrome&resultId=01987498-f715-719a-bc64-9e610b8007d0
A4: 11.1.3.4.1S001 Accedi | B4: =_xlfn.XLOOKUP(outTable[[#This Row],[ID Silk]],Tabella4[ID Silk],Tabella4[Titolo Defect],,0,1) -> APP INDABOX ANDROID - 11.1.3.4.1 Orientamento - S001 Accedi | C4: APP INDABOX ANDROID - 11.1.3.4.1 Orientamento - S001 Accedi: (#AAD712)_x000D_ S001 Accedi_x000D_ Requisito WCAG: 1.3.4_x000D_ Disabilità afflitte: Cognitive;Low Vision;Mobility_x000D_ Impatto Utente: 2 - Serious_x000D_ _x000D_ Descrizione_x000D_ 001 - ScreenOrientation - Le visualizzazioni devono essere conformi all'orientamento di visualizzazione preferito dall'utente. [Per saperne di più] (https://docs.deque.com/devtools-mobile/2024.2.14/en/android-screen-orientation)_x000D_ _x000D_ Esempio di violazione individuata sull'oggetto:_x000D_ 001 - con selettore No ID Available_x000D_ _x000D_ Dettaglio + screenshot (accedere con le seguenti credenziali: user, axeposte@gmail.com; password, Poste2024!)_x000D_ 001 - https://axe-mobile.deque.com/scan?userId=747da6b3-5f03-493b-bc9b-3a10276b7d6b&packageName=com.android.chrome&resultId=01987498-f715-719a-bc64-9e610b8007d0_x000D_ _x000D_ Possibile Metodologia Risolutiva:_x000D_ 001 - Rimuovi android:screenOrientation="portrait" per supportare sia landscape che portrait, salvo che non sia un requisito._x000D_ _x000D_ Occorrenze rilevate: 1_x000D_ _x000D_ Link al dettaglio requisito WCAG: https://www.w3.org/WAI/WCAG21/quickref/_x000D_ | D4: 2 - Serious | E4: (#AAD712) | G4: 2 - Serious | H4: S001 Accedi | I4: 11.1.3.4.1 | J4: 001 - ScreenOrientation - Le visualizzazioni devono essere conformi all'orientamento di visualizzazione preferito dall'utente. [Per saperne di più] (https://docs.deque.com/devtools-mobile/2024.2.14/en/android-screen-orientation) | K4: 001 - Rimuovi android:screenOrientation="portrait" per supportare sia landscape che portrait, salvo che non sia un requisito. | L4: 001 - https://axe-mobile.deque.com/scan?userId=747da6b3-5f03-493b-bc9b-3a10276b7d6b&packageName=com.android.chrome&resultId=01987498-f715-719a-bc64-9e610b8007d0
A5: 11.1.4.3.1S001 Accedi | B5: =_xlfn.XLOOKUP(outTable[[#This Row],[ID Silk]],Tabella4[ID Silk],Tabella4[Titolo Defect],,0,1) -> APP INDABOX ANDROID - 11.1.4.3.1 Contrasto (minimo) - S001 Accedi | C5: APP INDABOX ANDROID - 11.1.4.3.1 Contrasto (minimo) - S001 Accedi: (#AAD014)_x000D_ S001 Accedi_x000D_ Requisito WCAG: 1.4.3_x000D_ Disabilità afflitte: Colorblindness;Low Vision_x000D_ Impatto Utente: 2 - Serious_x000D_ _x000D_ Descrizione_x000D_ 001 - Contrasto del testo -_x000D_ _x000D_ Esempio di violazione individuata sull'oggetto:_x000D_ 001 - https://drive.google.com/file/d/1b3yG_Slc4Z8KE_PMwmczXyuudv_rPLY7/view?usp=drive_link con selettore [19,544][1061,810]_x000D_ _x000D_ Possibile Metodologia Risolutiva:_x000D_ 001 - Usa colori con un contrasto minimo di 4.5:1 per il testo normale e 3:1 per il testo grande. Controlla con strumenti come WebAIM o il contrast checker di Material Design._x000D_ _x000D_ Occorrenze rilevate: 1_x000D_ _x000D_ Link al dettaglio requisito WCAG: https://www.w3.org/WAI/WCAG21/quickref/_x000D_ | D5: 2 - Serious | E5: (#AAD014) | G5: 2 - Serious | H5: S001 Accedi | I5: 11.1.4.3.1 | J5: 001 - Contrasto del testo - | K5: 001 - Usa colori con un contrasto minimo di 4.5:1 per il testo normale e 3:1 per il testo grande. Controlla con strumenti come WebAIM o il contrast checker di Material Design. | L5: 0
A6: 11.2.5.3.1S001 Accedi | B6: =_xlfn.XLOOKUP(outTable[[#This Row],[ID Silk]],Tabella4[ID Silk],Tabella4[Titolo Defect],,0,1) -> APP INDABOX ANDROID - 11.2.5.3.1 Etichetta nel nome - S001 Accedi | C6: APP INDABOX ANDROID - 11.2.5.3.1 Etichetta nel nome - S001 Accedi: (#AAD713)_x000D_ S001 Accedi_x000D_ Requisito WCAG: 2.5.3_x000D_ Disabilità afflitte: Blind;Deafblind;Mobility_x000D_ Impatto Utente: 2 - Serious_x000D_ _x000D_ Descrizione_x000D_ 001 - LabelInName - Una vista focalizzabile accessibile deve garantire che il nome sia incluso nell'etichetta visibile. [Per saperne di più] (https://docs.deque.com/devtools-mobile/2024.2.14/en/android-label-in-name)_x000D_ _x000D_ Esempio di violazione individuata sull'oggetto:_x000D_ 001 - con selettore logo_x000D_ _x000D_ Dettaglio + screenshot (accedere con le seguenti credenziali: user, axeposte@gmail.com; password, Poste2024!)_x000D_ 001 - https://axe-mobile.deque.com/scan?userId=747da6b3-5f03-493b-bc9b-3a10276b7d6b&packageName=com.android.chrome&resultId=01987498-f715-719a-bc64-9e610b8007d0_x000D_ _x000D_ Possibile Metodologia Risolutiva:_x000D_ 001 - Assicurati che contentDescription o labelFor contengano l’etichetta visibile dell’elemento._x000D_ _x000D_ Occorrenze rilevate: 1_x000D_ _x000D_ Link al dettaglio requisito WCAG: https://www.w3.org/WAI/WCAG21/quickref/_x000D_ | D6: 2 - Serious | E6: (#AAD713) | G6: 2 - Serious | H6: S001 Accedi | I6: 11.2.5.3.1 | J6: 001 - LabelInName - Una vista focalizzabile accessibile deve garantire che il nome sia incluso nell'etichetta visibile. [Per saperne di più] (https://docs.deque.com/devtools-mobile/2024.2.14/en/android-label-in-name) | K6: 001 - Assicurati che contentDescription o labelFor contengano l’etichetta visibile dell’elemento. | L6: 001 - https://axe-mobile.deque.com/scan?userId=747da6b3-5f03-493b-bc9b-3a10276b7d6b&packageName=com.android.chrome&resultId=01987498-f715-719a-bc64-9e610b8007d0
A7: 11.4.1.2.1S001 Accedi | B7: =_xlfn.XLOOKUP(outTable[[#This Row],[ID Silk]],Tabella4[ID Silk],Tabella4[Titolo Defect],,0,1) -> APP INDABOX ANDROID - 11.4.1.2.1 Nome, ruolo, valore - S001 Accedi | C7: APP INDABOX ANDROID - 11.4.1.2.1 Nome, ruolo, valore - S001 Accedi: (#AAD1979)_x000D_ S001 Accedi_x000D_ Requisito WCAG: 4.1.2_x000D_ Disabilità afflitte: Blind;Low Vision;Mobility_x000D_ Impatto Utente: 3 - Moderate_x000D_ _x000D_ Descrizione_x000D_ 001 - EditTextName - Gli elementi di input di testo devono avere un nome accessibile disponibile per le tecnologie assistive come TalkBack e Voice Access. [Per saperne di più] (https://docs.deque.com/devtools-mobile/2024.2.14/en/android-edit-text-name)_x000D_ 002 - CheckBoxName - Qualsiasi elemento CheckBox deve avere un nome accessibile disponibile per le tecnologie assistive come TalkBack e Voice Access. [Per saperne di più] (https://docs.deque.com/devtools-mobile/2024.2.14/en/android-checkbox-name)_x000D_ 003 - Annuncio errato - Talkback legge in maniera errata un elemento(https://www.w3.org/WAI/WCAG21/Understanding/name-role-value)_x000D_ _x000D_ Esempio di violazione individuata sull'oggetto:_x000D_ 001 - con selettore No ID Available_x000D_ 002 - con selettore No ID Available_x000D_ 003 - Accedi con Google con selettore_x000D_ _x000D_ Dettaglio + screenshot (accedere con le seguenti credenziali: user, axeposte@gmail.com; password, Poste2024!)_x000D_ 001 - https://axe-mobile.deque.com/scan?userId=747da6b3-5f03-493b-bc9b-3a10276b7d6b&packageName=com.android.chrome&resultId=019874b6-b4db-71cf-b61c-3f04f6ecb1d6_x000D_ 002 - https://axe-mobile.deque.com/scan?userId=747da6b3-5f03-493b-bc9b-3a10276b7d6b&packageName=com.android.chrome&resultId=019874b6-b4db-71cf-b61c-3f04f6ecb1d6_x000D_ _x000D_ Possibile Metodologia Risolutiva:_x000D_ 001 - Usa android:hint oppure associa una TextView con android:labelFor._x000D_ 002 - Aggiungi un’etichetta visibile e/o android:contentDescription._x000D_ 003 - Fornire informazioni su ruolo, stato e valore su tutti i componenti dell'interfaccia utente_x000D_ _x000D_ Occorrenze rilevate: 3_x000D_ _x000D_ Link al dettaglio requisito WCAG: https://www.w3.org/WAI/WCAG21/quickref/_x000D_ | D7: 3 - Moderate | E7: (#AAD1979) | G7: 3 - Moderate | H7: S001 Accedi | I7: 11.4.1.2.1 | J7: 001 - EditTextName - Gli elementi di input di testo devono avere un nome accessibile disponibile per le tecnologie assistive come TalkBack e Voice Access. [Per saperne di più] (https://docs.deque.com/devtools-mobile/2024.2.14/en/android-edit-text-name)_x000D_ 002 - CheckBoxName - Qualsiasi elemento CheckBox deve avere un nome accessibile disponibile per le tecnologie assistive come TalkBack e Voice Access. [Per saperne di più] (https://docs.deque.com/devtools-mobile/2024.2.14/en/android-checkbox-name)_x000D_ 003 - Annuncio errato - Talkback legge in maniera errata un elemento(https://www.w3.org/WAI/WCAG21/Understanding/name-role-value) | K7: 001 - Usa android:hint oppure associa una TextView con android:labelFor._x000D_ 002 - Aggiungi un’etichetta visibile e/o android:contentDescription._x000D_ 003 - Fornire informazioni su ruolo, stato e valore su tutti i componenti dell'interfaccia utente | L7: 001 - https://axe-mobile.deque.com/scan?userId=747da6b3-5f03-493b-bc9b-3a10276b7d6b&packageName=com.android.chrome&resultId=019874b6-b4db-71cf-b61c-3f04f6ecb1d6_x000D_ 002 - https://axe-mobile.deque.com/scan?userId=747da6b3-5f03-493b-bc9b-3a10276b7d6b&packageName=com.android.chrome&resultId=019874b6-b4db-71cf-b61c-3f04f6ecb1d6
A8: 11.1.3.2.1S002 Registrazione | B8: =_xlfn.XLOOKUP(outTable[[#This Row],[ID Silk]],Tabella4[ID Silk],Tabella4[Titolo Defect],,0,1) -> APP INDABOX ANDROID - 11.1.3.2.1 Sequenza significativa - S002 Registrazione | C8: APP INDABOX ANDROID - 11.1.3.2.1 Sequenza significativa - S002 Registrazione: (#AAD690)_x000D_ S002 Registrazione_x000D_ Requisito WCAG: 1.3.2_x000D_ Disabilità afflitte: Blind;Cognitive;Low Vision;Mobility_x000D_ Impatto Utente: 1 - Critical_x000D_ _x000D_ Descrizione_x000D_ 001 - FocusableText - Le visualizzazioni contenenti testo devono essere attivabili per le tecnologie per l'accesso facilitato, ad esempio TalkBack. [Per saperne di più] (https://docs.deque.com/devtools-mobile/2024.2.14/en/android-focusable-text)_x000D_ _x000D_ Esempio di violazione individuata sull'oggetto:_x000D_ 001 - con selettore No ID Available_x000D_ _x000D_ Dettaglio + screenshot (accedere con le seguenti credenziali: user, axeposte@gmail.com; password, Poste2024!)_x000D_ 001 - https://axe-mobile.deque.com/scan?userId=747da6b3-5f03-493b-bc9b-3a10276b7d6b&packageName=com.android.chrome&resultId=01987498-918f-7639-bf08-09d26a0751d4_x000D_ _x000D_ Possibile Metodologia Risolutiva:_x000D_ 001 - Rimuovi android:focusable="true" dal testo statico non interattivo._x000D_ _x000D_ Occorrenze rilevate: 1_x000D_ _x000D_ Link al dettaglio requisito WCAG: https://www.w3.org/WAI/WCAG21/quickref/_x000D_ | D8: 1 - Critical | E8: (#AAD690) | G8: 1 - Critical | H8: S002 Registrazione | I8: 11.1.3.2.1 | J8: 001 - FocusableText - Le visualizzazioni contenenti testo devono essere attivabili per le tecnologie per l'accesso facilitato, ad esempio TalkBack. [Per saperne di più] (https://docs.deque.com/devtools-mobile/2024.2.14/en/android-focusable-text) | K8: 001 - Rimuovi android:focusable="true" dal testo statico non interattivo. | L8: 001 - https://axe-mobile.deque.com/scan?userId=747da6b3-5f03-493b-bc9b-3a10276b7d6b&packageName=com.android.chrome&resultId=01987498-918f-7639-bf08-09d26a0751d4
A9: 11.1.3.4.1S002 Registrazione | B9: =_xlfn.XLOOKUP(outTable[[#This Row],[ID Silk]],Tabella4[ID Silk],Tabella4[Titolo Defect],,0,1) -> APP INDABOX ANDROID - 11.1.3.4.1 Orientamento - S002 Registrazione | C9: APP INDABOX ANDROID - 11.1.3.4.1 Orientamento - S002 Registrazione: (#AAD684)_x000D_ S002 Registrazione_x000D_ Requisito WCAG: 1.3.4_x000D_ Disabilità afflitte: Cognitive;Low Vision;Mobility_x000D_ Impatto Utente: 2 - Serious_x000D_ _x000D_ Descrizione_x000D_ 001 - ScreenOrientation - Le visualizzazioni devono essere conformi all'orientamento di visualizzazione preferito dall'utente. [Per saperne di più] (https://docs.deque.com/devtools-mobile/2024.2.14/en/android-screen-orientation)_x000D_ _x000D_ Esempio di violazione individuata sull'oggetto:_x000D_ 001 - con selettore No ID Available_x000D_ _x000D_ Dettaglio + screenshot (accedere con le seguenti credenziali: user, axeposte@gmail.com; password, Poste2024!)_x000D_ 001 - https://axe-mobile.deque.com/scan?userId=747da6b3-5f03-493b-bc9b-3a10276b7d6b&packageName=com.android.chrome&resultId=01987498-918f-7639-bf08-09d26a0751d4_x000D_ _x000D_ Possibile Metodologia Risolutiva:_x000D_ 001 - Rimuovi android:screenOrientation="portrait" per supportare sia landscape che portrait, salvo che non sia un requisito._x000D_ _x000D_ Occorrenze rilevate: 1_x000D_ _x000D_ Link al dettaglio requisito WCAG: https://www.w3.org/WAI/WCAG21/quickref/_x000D_ | D9: 2 - Serious | E9: (#AAD684) | G9: 2 - Serious | H9: S002 Registrazione | I9: 11.1.3.4.1 | J9: 001 - ScreenOrientation - Le visualizzazioni devono essere conformi all'orientamento di visualizzazione preferito dall'utente. [Per saperne di più] (https://docs.deque.com/devtools-mobile/2024.2.14/en/android-screen-orientation) | K9: 001 - Rimuovi android:screenOrientation="portrait" per supportare sia landscape che portrait, salvo che non sia un requisito. | L9: 001 - https://axe-mobile.deque.com/scan?userId=747da6b3-5f03-493b-bc9b-3a10276b7d6b&packageName=com.android.chrome&resultId=01987498-918f-7639-bf08-09d26a0751d4
A10: 11.1.4.3.1S002 Registrazione | B10: =_xlfn.XLOOKUP(outTable[[#This Row],[ID Silk]],Tabella4[ID Silk],Tabella4[Titolo Defect],,0,1) -> APP INDABOX ANDROID - 11.1.4.3.1 Contrasto (minimo) - S002 Registrazione | C10: APP INDABOX ANDROID - 11.1.4.3.1 Contrasto (minimo) - S002 Registrazione: (#AAD001)_x000D_ S002 Registrazione_x000D_ Requisito WCAG: 1.4.3_x000D_ Disabilità afflitte: Colorblindness;Low Vision_x000D_ Impatto Utente: 2 - Serious_x000D_ _x000D_ Descrizione_x000D_ 001 - Contrasto del testo -_x000D_ _x000D_ Esempio di violazione individuata sull'oggetto:_x000D_ 001 - https://drive.google.com/file/d/1Ky3onw1yTzntxdtp2e6NbCHhxzGdkenw/view?usp=drive_link con selettore [19,571][1061,838]_x000D_ _x000D_ Possibile Metodologia Risolutiva:_x000D_ 001 - Usa colori con un contrasto minimo di 4.5:1 per il testo normale e 3:1 per il testo grande. Controlla con strumenti come WebAIM o il contrast checker di Material Design._x000D_ _x000D_ Occorrenze rilevate: 1_x000D_ _x000D_ Link al dettaglio requisito WCAG: https://www.w3.org/WAI/WCAG21/quickref/_x000D_ | D10: 2 - Serious | E10: (#AAD001) | G10: 2 - Serious | H10: S002 Registrazione | I10: 11.1.4.3.1 | J10: 001 - Contrasto del testo - | K10: 001 - Usa colori con un contrasto minimo di 4.5:1 per il testo normale e 3:1 per il testo grande. Controlla con strumenti come WebAIM o il contrast checker di Material Design. | L10: 0

Sheet Foglio2
A3: Etichette di riga | B3: Conteggio di ID Silk
A4: 5109 | B4: 1 | F4: =COUNTIF(B4:B53,">1") -> 42 | J4: 8
A5: 5110 | B5: 104 | J5: 42
A6: 5111 | B6: 7
A7: 5112 | B7: 44
A8: 5113 | B8: 70
A9: 5114 | B9: 9
A10: 5115 | B10: 22
A11: 5116 | B11: 2
A12: 5117 | B12: 5
A13: 5118 | B13: 20
A14: 5119 | B14: 2
A15: 5120 | B15: 70
A16: 5121 | B16: 4
A17: 5122 | B17: 79
... A53: 5158 | B53: 1
A54: Totale complessivo | B54: 1422

Sheet Not Passed
A1: ID Silk | B1: subID | C1: #ID | D1: ID defectXsilk | E1: Componente | F1: Livello | G1: Criterio | H1: UNI CEI EN 301549 | I1: User Impact | J1: Disabilities | K1: Titolo | L1: Descrizione | M1: Rejected Element | N1: Detail | O1: Pagina | P1: Page ID | Q1: Tool | R1: IssueID | S1: Items Explanation | T1: Soluzione note aggiuntive | U1: Diffusione | V1: Servizio | W1: Share URL | X1: Severity | Y1: Titolo Defect | Z1: Description Defect | AA1: Colonna1 | AB1: Colonna2 | AC1: Colonna3 | AD1: Colonna4 | AE1: Caricato su Silk | AF1: Testo silk | AG1: HC_01 | AH1: HC_ID | AI1: HC Desc | AJ1: HC Viol | AK1: HC Screen | AL1: HC Solution | AM1: URL
A2: =Tabella4[[#This Row],[UNI CEI EN 301549]]&Tabella4[[#This Row],[Servizio]] -> 11.1.4.3.1S002 Registrazione | B2: =Tabella4[[#This Row],[IssueID]]&Tabella4[[#This Row],[Servizio]] -> S002 Registrazione | C2: AAD001 | D2: ="(#"&Tabella4[[#This Row],['#ID]]&")" -> (#AAD001) | E2: Android | F2: AA | G2: 1.4.3 | H2: 11.1.4.3.1 | I2: 2 - Serious | J2: Colorblindness;Low Vision | K2: Contrasto del testo | M2: [19,571][1061,838] | N2: https://drive.google.com/file/d/1Ky3onw1yTzntxdtp2e6NbCHhxzGdkenw/view?usp=drive_link | O2: Home password dimenticata.txt | P2: #1 | Q2: Accessibility Scanner | S2: https://support.google.com/accessibility/android/answer/7158390?sjid=7294552562745413635-EU | T2: Usa colori con un contrasto minimo di 4.5:1 per il testo normale e 3:1 per il testo grande. Controlla con strumenti come WebAIM o il contrast checker di Material Design. | U2: =COUNTIFS(Tabella4[Rejected Element],Tabella4[[#This Row],[Rejected Element]]) -> 1 | V2: S002 Registrazione | X2: =Tabella4[[#This Row],[User Impact]] -> 2 - Serious | Y2: =_xlfn.CONCAT("APP INDABOX ANDROID - ",Tabella4[[#This Row],[UNI CEI EN 301549]]," ",_xlfn.XLOOKUP(Tabella4[[#This Row],[Criterio]],Tabella5[ID],Tabella5[Criterio di successo],"")," - ",Tabella4[[#This Row],[Servizio]]) -> APP INDABOX ANDROID - 11.1.4.3.1 Contrasto (minimo) - S002 Registrazione | Z2: =_xlfn.CONCAT(Tabella4[[#This Row],[Titolo Defect]]," ",Tabella4[[#This Row],[ID defectXsilk]],CHAR(10),Tabella4[[#This Row],[Servizio]],CHAR(10),_xlfn.CONCAT("Requisito: WCAG ",Tabella4[[#This Row],[Criterio]],CHAR(10),"Disabilità afflitte: ",Tabella4[[#This Row],[Disabilities]],CHAR(10),"Impatto Utente: ",Tabella4[[#This Row],[User Impact]],CHAR(10),CHAR(10),"Descrizione: ",Tabella4[[#This Row],[Titolo]]," - ",Tabella4[[#This Row],[Descrizione]],CHAR(10),CHAR(10),"Esempio di violazione individuata sull'oggetto: ",CHAR(10)," - ",Tabella4[[#This Row],[Detail]]," con selettore: ",CHAR(10),Tabella4[[#This Row],[Rejected Element]],CHAR(10),CHAR(10),"Dettaglio + screenshot (accedere con le seguenti credenziali: user, axeposte@gmail.com; password, Poste2024!): ",Tabella4[[#This Row],[Share URL]],CHAR(10)),CHAR(10),"Possibile metodologia risolutiva:"&CHAR(10),Tabella4[[#This Row],[Soluzione note aggiuntive]],CHAR(10),CHAR(10),"File di log (occorrenze rilevate: "&COUNTIF(Tabella4[ID Silk],Tabella4[[#This Row],[ID Silk]])&"): https://posteitaliane.sharepoint.com/:x:/r/teams/ACCESSIBILITRISULTATIVERIFICHETECNICHE/Shared%20Documents/TGPOSTE_APP/TGPOSTE_APP/LOG/Log.xlsx?d=w630300a71bd74143a1658fe5ab688bc4&csf=1&web=1&e=Y9XHGL",CHAR(10),CHAR(10),"Link al dettaglio requisito WCAG: ",_xlfn.XLOOKUP(Tabella4[[#This Row],[UNI CEI EN 301549]],'Dati input'!F:F,'Dati input'!H:H,"",0)) -> APP INDABOX ANDROID - 11.1.4.3.1 Contrasto (minimo) - S002 Registrazione (#AAD001) S002 Registrazione Requisito: WCAG 1.4.3 Disabilità afflitte: Colorblindness;Low Vision Impatto Utente: 2 - Serious Descrizione: Contrasto del testo - Esempio di violazione individuata sull'oggetto: - https://drive.google.com/file/d/1Ky3onw1yTzntxdtp2e6NbCHhxzGdkenw/view?usp=drive_link con selettore: [19,571][1061,838] Dettaglio + screenshot (accedere con le seguenti credenziali: user, axeposte@gmail.com; password, Poste2024!): Possibile metodologia risolutiva: Usa colori con un contrasto minimo di 4.5:1 per il testo normale e 3:1 per il testo grande. Controlla con strumenti come WebAIM o il contrast checker di Material Design. File di log (occorrenze rilevate: 5): https://posteitaliane.sharepoint.com/:x:/r/teams/ACCESSIBILITRISULTATIVERIFICHETECNICHE/Shared%20Documents/TGPOSTE_APP/TGPOSTE_APP/LOG/Log.xlsx?d=w630300a71bd74143a1658fe5ab688bc4&csf=1&web=1&e=Y9XHGL Link al dettaglio requisito WCAG: | AE2: =_xlfn.XLOOKUP(Tabella4[[#This Row],[ID Silk]],outTable[ID Silk],outTable[Numero ticket ],,0,1) -> 0 | AH2: =Tabella4[[#This Row],[Caricato su Silk]]&Tabella4[[#This Row],[HC_01]] -> 0 | AI2: =Tabella4[[#This Row],[HC_ID]]&": "&Tabella4[[#This Row],[Descrizione]] -> 0: | AJ2: =Tabella4[[#This Row],[HC_ID]]&": - "&Tabella4[[#This Row],[Detail]]&" con selettore: "&Tabella4[[#This Row],[Rejected Element]] -> 0: - https://drive.google.com/file/d/1Ky3onw1yTzntxdtp2e6NbCHhxzGdkenw/view?usp=drive_link con selettore: [19,571][1061,838] | AK2: =Tabella4[[#This Row],[HC_ID]]&": "&Tabella4[[#This Row],[Share URL]] -> 0: | AL2: =Tabella4[[#This Row],[HC_ID]]&": "&Tabella4[[#This Row],[Soluzione note aggiuntive]] -> 0: Usa colori con un contrasto minimo di 4.5:1 per il testo normale e 3:1 per il testo grande. Controlla con strumenti come WebAIM o il contrast checker di Material Design.
A3: =Tabella4[[#This Row],[UNI CEI EN 301549]]&Tabella4[[#This Row],[Servizio]] -> 11.2.5.8.1S002 Registrazione | B3: =Tabella4[[#This Row],[IssueID]]&Tabella4[[#This Row],[Servizio]] -> S002 Registrazione | C3: AAD002 | D3: ="(#"&Tabella4[[#This Row],['#ID]]&")" -> (#AAD002) | E3: Android | F3: AA | G3: 2.5.8 | H3: 11.2.5.8.1 | I3: 2 - Serious | J3: Blind;Low Vision;Mobility | K3: Touch target | M3: [836,139][1028,181] | N3: https://drive.google.com/file/d/1Ky3onw1yTzntxdtp2e6NbCHhxzGdkenw/view?usp=drive_link | O3: Home password dimenticata.txt | P3: #1 | Q3: Accessibility Scanner | S3: https://support.google.com/accessibility/android/answer/7101858?sjid=12879261749095892834-EU | T3: Aumenta le dimensioni minime degli elementi cliccabili o aggiungi padding/click area extra invisibile per raggiungere la dimensione minima. | U3: =COUNTIFS(Tabella4[Rejected Element],Tabella4[[#This Row],[Rejected Element]]) -> 15 | V3: S002 Registrazione | X3: =Tabella4[[#This Row],[User Impact]] -> 2 - Serious | Y3: =_xlfn.CONCAT("APP INDABOX ANDROID - ",Tabella4[[#This Row],[UNI CEI EN 301549]]," ",_xlfn.XLOOKUP(Tabella4[[#This Row],[Criterio]],Tabella5[ID],Tabella5[Criterio di successo],"")," - ",Tabella4[[#This Row],[Servizio]]) -> APP INDABOX ANDROID - 11.2.5.8.1 Dimensione dell'obiettivo (minimo) - S002 Registrazione | Z3: =_xlfn.CONCAT(Tabella4[[#This Row],[Titolo Defect]]," ",Tabella4[[#This Row],[ID defectXsilk]],CHAR(10),Tabella4[[#This Row],[Servizio]],CHAR(10),_xlfn.CONCAT("Requisito: WCAG ",Tabella4[[#This Row],[Criterio]],CHAR(10),"Disabilità afflitte: ",Tabella4[[#This Row],[Disabilities]],CHAR(10),"Impatto Utente: ",Tabella4[[#This Row],[User Impact]],CHAR(10),CHAR(10),"Descrizione: ",Tabella4[[#This Row],[Titolo]]," - ",Tabella4[[#This Row],[Descrizione]],CHAR(10),CHAR(10),"Esempio di violazione individuata sull'oggetto: ",CHAR(10)," - ",Tabella4[[#This Row],[Detail]]," con selettore: ",CHAR(10),Tabella4[[#This Row],[Rejected Element]],CHAR(10),CHAR(10),"Dettaglio + screenshot (accedere con le seguenti credenziali: user, axeposte@gmail.com; password, Poste2024!): ",Tabella4[[#This Row],[Share URL]],CHAR(10)),CHAR(10),"Possibile metodologia risolutiva:"&CHAR(10),Tabella4[[#This Row],[Soluzione note aggiuntive]],CHAR(10),CHAR(10),"File di log (occorrenze rilevate: "&COUNTIF(Tabella4[ID Silk],Tabella4[[#This Row],[ID Silk]])&"): https://posteitaliane.sharepoint.com/:x:/r/teams/ACCESSIBILITRISULTATIVERIFICHETECNICHE/Shared%20Documents/TGPOSTE_APP/TGPOSTE_APP/LOG/Log.xlsx?d=w630300a71bd74143a1658fe5ab688bc4&csf=1&web=1&e=Y9XHGL",CHAR(10),CHAR(10),"Link al dettaglio requisito WCAG: ",_xlfn.XLOOKUP(Tabella4[[#This Row],[UNI CEI EN 301549]],'Dati input'!F:F,'Dati input'!H:H,"",0)) -> APP INDABOX ANDROID - 11.2.5.8.1 Dimensione dell'obiettivo (minimo) - S002 Registrazione (#AAD002) S002 Registrazione Requisito: WCAG 2.5.8 Disabilità afflitte: Blind;Low Vision;Mobility Impatto Utente: 2 - Serious Descrizione: Touch target - Esempio di violazione individuata sull'oggetto: - https://drive.google.com/file/d/1Ky3onw1yTzntxdtp2e6NbCHhxzGdkenw/view?usp=drive_link con selettore: [836,139][1028,181] Dettaglio + screenshot (accedere con le seguenti credenziali: user, axeposte@gmail.com; password, Poste2024!): Possibile metodologia risolutiva: Aumenta le dimensioni minime degli elementi cliccabili o aggiungi padding/click area extra invisibile per raggiungere la dimensione minima. File di log (occorrenze rilevate: 31): https://posteitaliane.sharepoint.com/:x:/r/teams/ACCESSIBILITRISULTATIVERIFICHETECNICHE/Shared%20Documents/TGPOSTE_APP/TGPOSTE_APP/LOG/Log.xlsx?d=w630300a71bd74143a1658fe5ab688bc4&csf=1&web=1&e=Y9XHGL Link al dettaglio requisito WCAG: | AE3: =_xlfn.XLOOKUP(Tabella4[[#This Row],[ID Silk]],outTable[ID Silk],outTable[Numero ticket ],,0,1) -> #N/A | AH3: =Tabella4[[#This Row],[Caricato su Silk]]&Tabella4[[#This Row],[HC_01]] -> #N/A | AI3: =Tabella4[[#This Row],[HC_ID]]&": "&Tabella4[[#This Row],[Descrizione]] -> #N/A | AJ3: =Tabella4[[#This Row],[HC_ID]]&": - "&Tabella4[[#This Row],[Detail]]&" con selettore: "&Tabella4[[#This Row],[Rejected Element]] -> #N/A | AK3: =Tabella4[[#This Row],[HC_ID]]&": "&Tabella4[[#This Row],[Share URL]] -> #N/A | AL3: =Tabella4[[#This Row],[HC_ID]]&": "&Tabella4[[#This Row],[Soluzione note aggiuntive]] -> #N/A
A4: =Tabella4[[#This Row],[UNI CEI EN 301549]]&Tabella4[[#This Row],[Servizio]] -> 11.2.5.8.1S002 Registrazione | B4: =Tabella4[[#This Row],[IssueID]]&Tabella4[[#This Row],[Servizio]] -> S002 Registrazione | C4: AAD003 | D4: ="(#"&Tabella4[[#This Row],['#ID]]&")" -> (#AAD003) | E4: Android | F4: AA | G4: 2.5.8 | H4: 11.2.5.8.1 | I4: 2 - Serious | J4: Blind;Low Vision;Mobility | K4: Touch target | M4: [195,225][297,271] | N4: https://drive.google.com/file/d/1Ky3onw1yTzntxdtp2e6NbCHhxzGdkenw/view?usp=drive_link | O4: Home password dimenticata.txt | P4: #1 | Q4: Accessibility Scanner | S4: https://support.google.com/accessibility/android/answer/7101858?sjid=12879261749095892834-EU | T4: Aumenta le dimensioni minime degli elementi cliccabili o aggiungi padding/click area extra invisibile per raggiungere la dimensione minima. | U4: =COUNTIFS(Tabella4[Rejected Element],Tabella4[[#This Row],[Rejected Element]]) -> 14 | V4: S002 Registrazione | X4: =Tabella4[[#This Row],[User Impact]] -> 2 - Serious | Y4: =_xlfn.CONCAT("APP INDABOX ANDROID - ",Tabella4[[#This Row],[UNI CEI EN 301549]]," ",_xlfn.XLOOKUP(Tabella4[[#This Row],[Criterio]],Tabella5[ID],Tabella5[Criterio di successo],"")," - ",Tabella4[[#This Row],[Servizio]]) -> APP INDABOX ANDROID - 11.2.5.8.1 Dimensione dell'obiettivo (minimo) - S002 Registrazione | Z4: =_xlfn.CONCAT(Tabella4[[#This Row],[Titolo Defect]]," ",Tabella4[[#This Row],[ID defectXsilk]],CHAR(10),Tabella4[[#This Row],[Servizio]],CHAR(10),_xlfn.CONCAT("Requisito: WCAG ",Tabella4[[#This Row],[Criterio]],CHAR(10),"Disabilità afflitte: ",Tabella4[[#This Row],[Disabilities]],CHAR(10),"Impatto Utente: ",Tabella4[[#This Row],[User Impact]],CHAR(10),CHAR(10),"Descrizione: ",Tabella4[[#This Row],[Titolo]]," - ",Tabella4[[#This Row],[Descrizione]],CHAR(10),CHAR(10),"Esempio di violazione individuata sull'oggetto: ",CHAR(10)," - ",Tabella4[[#This Row],[Detail]]," con selettore: ",CHAR(10),Tabella4[[#This Row],[Rejected Element]],CHAR(10),CHAR(10),"Dettaglio + screenshot (accedere con le seguenti credenziali: user, axeposte@gmail.com; password, Poste2024!): ",Tabella4[[#This Row],[Share URL]],CHAR(10)),CHAR(10),"Possibile metodologia risolutiva:"&CHAR(10),Tabella4[[#This Row],[Soluzione note aggiuntive]],CHAR(10),CHAR(10),"File di log (occorrenze rilevate: "&COUNTIF(Tabella4[ID Silk],Tabella4[[#This Row],[ID Silk]])&"): https://posteitaliane.sharepoint.com/:x:/r/teams/ACCESSIBILITRISULTATIVERIFICHETECNICHE/Shared%20Documents/TGPOSTE_APP/TGPOSTE_APP/LOG/Log.xlsx?d=w630300a71bd74143a1658fe5ab688bc4&csf=1&web=1&e=Y9XHGL",CHAR(10),CHAR(10),"Link al dettaglio requisito WCAG: ",_xlfn.XLOOKUP(Tabella4[[#This Row],[UNI CEI EN 301549]],'Dati input'!F:F,'Dati input'!H:H,"",0)) -> APP INDABOX ANDROID - 11.2.5.8.1 Dimensione dell'obiettivo (minimo) - S002 Registrazione (#AAD003) S002 Registrazione Requisito: WCAG 2.5.8 Disabilità afflitte: Blind;Low Vision;Mobility Impatto Utente: 2 - Serious Descrizione: Touch target - Esempio di violazione individuata sull'oggetto: - https://drive.google.com/file/d/1Ky3onw1yTzntxdtp2e6NbCHhxzGdkenw/view?usp=drive_link con selettore: [195,225][297,271] Dettaglio + screenshot (accedere con le seguenti credenziali: user, axeposte@gmail.com; password, Poste2024!): Possibile metodologia risolutiva: Aumenta le dimensioni minime degli elementi cliccabili o aggiungi padding/click area extra invisibile per raggiungere la dimensione minima. File di log (occorrenze rilevate: 31): https://posteitaliane.sharepoint.com/:x:/r/teams/ACCESSIBILITRISULTATIVERIFICHETECNICHE/Shared%20Documents/TGPOSTE_APP/TGPOSTE_APP/LOG/Log.xlsx?d=w630300a71bd74143a1658fe5ab688bc4&csf=1&web=1&e=Y9XHGL Link al dettaglio requisito WCAG: | AE4: =_xlfn.XLOOKUP(Tabella4[[#This Row],[ID Silk]],outTable[ID Silk],outTable[Numero ticket ],,0,1) -> #N/A | AH4: =Tabella4[[#This Row],[Caricato su Silk]]&Tabella4[[#This Row],[HC_01]] -> #N/A | AI4: =Tabella4[[#This Row],[HC_ID]]&": "&Tabella4[[#This Row],[Descrizione]] -> #N/A | AJ4: =Tabella4[[#This Row],[HC_ID]]&": - "&Tabella4[[#This Row],[Detail]]&" con selettore: "&Tabella4[[#This Row],[Rejected Element]] -> #N/A | AK4: =Tabella4[[#This Row],[HC_ID]]&": "&Tabella4[[#This Row],[Share URL]] -> #N/A | AL4: =Tabella4[[#This Row],[HC_ID]]&": "&Tabella4[[#This Row],[Soluzione note aggiuntive]] -> #N/A
A5: =Tabella4[[#This Row],[UNI CEI EN 301549]]&Tabella4[[#This Row],[Servizio]] -> 11.2.5.8.1S002 Registrazione | B5: =Tabella4[[#This Row],[IssueID]]&Tabella4[[#This Row],[Servizio]] -> S002 Registrazione | C5: AAD004 | D5: ="(#"&Tabella4[[#This Row],['#ID]]&")" -> (#AAD004) | E5: Android | F5: AA | G5: 2.5.8 | H5: 11.2.5.8.1 | I5: 2 - Serious | J5: Blind;Low Vision;Mobility | K5: Touch target | M5: [341,225][486,271] | N5: https://drive.google.com/file/d/1Ky3onw1yTzntxdtp2e6NbCHhxzGdkenw/view?usp=drive_link | O5: Home password dimenticata.txt | P5: #1 | Q5: Accessibility Scanner | S5: https://support.google.com/accessibility/android/answer/7101858?sjid=12879261749095892834-EU | T5: Aumenta le dimensioni minime degli elementi cliccabili o aggiungi padding/click area extra invisibile per raggiungere la dimensione minima. | U5: =COUNTIFS(Tabella4[Rejected Element],Tabella4[[#This Row],[Rejected Element]]) -> 14 | V5: S002 Registrazione | X5: =Tabella4[[#This Row],[User Impact]] -> 2 - Serious | Y5: =_xlfn.CONCAT("APP INDABOX ANDROID - ",Tabella4[[#This Row],[UNI CEI EN 301549]]," ",_xlfn.XLOOKUP(Tabella4[[#This Row],[Criterio]],Tabella5[ID],Tabella5[Criterio di successo],"")," - ",Tabella4[[#This Row],[Servizio]]) -> APP INDABOX ANDROID - 11.2.5.8.1 Dimensione dell'obiettivo (minimo) - S002 Registrazione | Z5: =_xlfn.CONCAT(Tabella4[[#This Row],[Titolo Defect]]," ",Tabella4[[#This Row],[ID defectXsilk]],CHAR(10),Tabella4[[#This Row],[Servizio]],CHAR(10),_xlfn.CONCAT("Requisito: WCAG ",Tabella4[[#This Row],[Criterio]],CHAR(10),"Disabilità afflitte: ",Tabella4[[#This Row],[Disabilities]],CHAR(10),"Impatto Utente: ",Tabella4[[#This Row],[User Impact]],CHAR(10),CHAR(10),"Descrizione: ",Tabella4[[#This Row],[Titolo]]," - ",Tabella4[[#This Row],[Descrizione]],CHAR(10),CHAR(10),"Esempio di violazione individuata sull'oggetto: ",CHAR(10)," - ",Tabella4[[#This Row],[Detail]]," con selettore: ",CHAR(10),Tabella4[[#This Row],[Rejected Element]],CHAR(10),CHAR(10),"Dettaglio + screenshot (accedere con le seguenti credenziali: user, axeposte@gmail.com; password, Poste2024!): ",Tabella4[[#This Row],[Share URL]],CHAR(10)),CHAR(10),"Possibile metodologia risolutiva:"&CHAR(10),Tabella4[[#This Row],[Soluzione note aggiuntive]],CHAR(10),CHAR(10),"File di log (occorrenze rilevate: "&COUNTIF(Tabella4[ID Silk],Tabella4[[#This Row],[ID Silk]])&"): https://posteitaliane.sharepoint.com/:x:/r/teams/ACCESSIBILITRISULTATIVERIFICHETECNICHE/Shared%20Documents/TGPOSTE_APP/TGPOSTE_APP/LOG/Log.xlsx?d=w630300a71bd74143a1658fe5ab688bc4&csf=1&web=1&e=Y9XHGL",CHAR(10),CHAR(10),"Link al dettaglio requisito WCAG: ",_xlfn.XLOOKUP(Tabella4[[#This Row],[UNI CEI EN 301549]],'Dati input'!F:F,'Dati input'!H:H,"",0)) -> APP INDABOX ANDROID - 11.2.5.8.1 Dimensione dell'obiettivo (minimo) - S002 Registrazione (#AAD004) S002 Registrazione Requisito: WCAG 2.5.8 Disabilità afflitte: Blind;Low Vision;Mobility Impatto Utente: 2 - Serious Descrizione: Touch target - Esempio di violazione individuata sull'oggetto: - https://drive.google.com/file/d/1Ky3onw1yTzntxdtp2e6NbCHhxzGdkenw/view?usp=drive_link con selettore: [341,225][486,271] Dettaglio + screenshot (accedere con le seguenti credenziali: user, axeposte@gmail.com; password, Poste2024!): Possibile metodologia risolutiva: Aumenta le dimensioni minime degli elementi cliccabili o aggiungi padding/click area extra invisibile per raggiungere la dimensione minima. File di log (occorrenze rilevate: 31): https://posteitaliane.sharepoint.com/:x:/r/teams/ACCESSIBILITRISULTATIVERIFICHETECNICHE/Shared%20Documents/TGPOSTE_APP/TGPOSTE_APP/LOG/Log.xlsx?d=w630300a71bd74143a1658fe5ab688bc4&csf=1&web=1&e=Y9XHGL Link al dettaglio requisito WCAG: | AE5: =_xlfn.XLOOKUP(Tabella4[[#This Row],[ID Silk]],outTable[ID Silk],outTable[Numero ticket ],,0,1) -> #N/A | AH5: =Tabella4[[#This Row],[Caricato su Silk]]&Tabella4[[#This Row],[HC_01]] -> #N/A | AI5: =Tabella4[[#This Row],[HC_ID]]&": "&Tabella4[[#This Row],[Descrizione]] -> #N/A | AJ5: =Tabella4[[#This Row],[HC_ID]]&": - "&Tabella4[[#This Row],[Detail]]&" con selettore: "&Tabella4[[#This Row],[Rejected Element]] -> #N/A | AK5: =Tabella4[[#This Row],[HC_ID]]&": "&Tabella4[[#This Row],[Share URL]] -> #N/A | AL5: =Tabella4[[#This Row],[HC_ID]]&": "&Tabella4[[#This Row],[Soluzione note aggiuntive]] -> #N/A
A6: =Tabella4[[#This Row],[UNI CEI EN 301549]]&Tabella4[[#This Row],[Servizio]] -> 11.2.5.8.1S002 Registrazione | B6: =Tabella4[[#This Row],[IssueID]]&Tabella4[[#This Row],[Servizio]] -> S002 Registrazione | C6: AAD005 | D6: ="(#"&Tabella4[[#This Row],['#ID]]&")" -> (#AAD005) | E6: Android | F6: AA | G6: 2.5.8 | H6: 11.2.5.8.1 | I6: 2 - Serious | J6: Blind;Low Vision;Mobility | K6: Touch target | M6: [528,225][613,271] | N6: https://drive.google.com/file/d/1Ky3onw1yTzntxdtp2e6NbCHhxzGdkenw/view?usp=drive_link | O6: Home password dimenticata.txt | P6: #1 | Q6: Accessibility Scanner | S6: https://support.google.com/accessibility/android/answer/7101858?sjid=12879261749095892834-EU | T6: Aumenta le dimensioni minime degli elementi cliccabili o aggiungi padding/click area extra invisibile per raggiungere la dimensione minima. | U6: =COUNTIFS(Tabella4[Rejected Element],Tabella4[[#This Row],[Rejected Element]]) -> 14 | V6: S002 Registrazione | X6: =Tabella4[[#This Row],[User Impact]] -> 2 - Serious | Y6: =_xlfn.CONCAT("APP INDABOX ANDROID - ",Tabella4[[#This Row],[UNI CEI EN 301549]]," ",_xlfn.XLOOKUP(Tabella4[[#This Row],[Criterio]],Tabella5[ID],Tabella5[Criterio di successo],"")," - ",Tabella4[[#This Row],[Servizio]]) -> APP INDABOX ANDROID - 11.2.5.8.1 Dimensione dell'obiettivo (minimo) - S002 Registrazione | Z6: =_xlfn.CONCAT(Tabella4[[#This Row],[Titolo Defect]]," ",Tabella4[[#This Row],[ID defectXsilk]],CHAR(10),Tabella4[[#This Row],[Servizio]],CHAR(10),_xlfn.CONCAT("Requisito: WCAG ",Tabella4[[#This Row],[Criterio]],CHAR(10),"Disabilità afflitte: ",Tabella4[[#This Row],[Disabilities]],CHAR(10),"Impatto Utente: ",Tabella4[[#This Row],[User Impact]],CHAR(10),CHAR(10),"Descrizione: ",Tabella4[[#This Row],[Titolo]]," - ",Tabella4[[#This Row],[Descrizione]],CHAR(10),CHAR(10),"Esempio di violazione individuata sull'oggetto: ",CHAR(10)," - ",Tabella4[[#This Row],[Detail]]," con selettore: ",CHAR(10),Tabella4[[#This Row],[Rejected Element]],CHAR(10),CHAR(10),"Dettaglio + screenshot (accedere con le seguenti credenziali: user, axeposte@gmail.com; password, Poste2024!): ",Tabella4[[#This Row],[Share URL]],CHAR(10)),CHAR(10),"Possibile metodologia risolutiva:"&CHAR(10),Tabella4[[#This Row],[Soluzione note aggiuntive]],CHAR(10),CHAR(10),"File di log (occorrenze rilevate: "&COUNTIF(Tabella4[ID Silk],Tabella4[[#This Row],[ID Silk]])&"): https://posteitaliane.sharepoint.com/:x:/r/teams/ACCESSIBILITRISULTATIVERIFICHETECNICHE/Shared%20Documents/TGPOSTE_APP/TGPOSTE_APP/LOG/Log.xlsx?d=w630300a71bd74143a1658fe5ab688bc4&csf=1&web=1&e=Y9XHGL",CHAR(10),CHAR(10),"Link al dettaglio requisito WCAG: ",_xlfn.XLOOKUP(Tabella4[[#This Row],[UNI CEI EN 301549]],'Dati input'!F:F,'Dati input'!H:H,"",0)) -> APP INDABOX ANDROID - 11.2.5.8.1 Dimensione dell'obiettivo (minimo) - S002 Registrazione (#AAD005) S002 Registrazione Requisito: WCAG 2.5.8 Disabilità afflitte: Blind;Low Vision;Mobility Impatto Utente: 2 - Serious Descrizione: Touch target - Esempio di violazione individuata sull'oggetto: - https://drive.google.com/file/d/1Ky3onw1yTzntxdtp2e6NbCHhxzGdkenw/view?usp=drive_link con selettore: [528,225][613,271] Dettaglio + screenshot (accedere con le seguenti credenziali: user, axeposte@gmail.com; password, Poste2024!): Possibile metodologia risolutiva: Aumenta le dimensioni minime degli elementi cliccabili o aggiungi padding/click area extra invisibile per raggiungere la dimensione minima. File di log (occorrenze rilevate: 31): https://posteitaliane.sharepoint.com/:x:/r/teams/ACCESSIBILITRISULTATIVERIFICHETECNICHE/Shared%20Documents/TGPOSTE_APP/TGPOSTE_APP/LOG/Log.xlsx?d=w630300a71bd74143a1658fe5ab688bc4&csf=1&web=1&e=Y9XHGL Link al dettaglio requisito WCAG: | AE6: =_xlfn.XLOOKUP(Tabella4[[#This Row],[ID Silk]],outTable[ID Silk],outTable[Numero ticket ],,0,1) -> #N/A | AH6: =Tabella4[[#This Row],[Caricato su Silk]]&Tabella4[[#This Row],[HC_01]] -> #N/A | AI6: =Tabella4[[#This Row],[HC_ID]]&": "&Tabella4[[#This Row],[Descrizione]] -> #N/A | AJ6: =Tabella4[[#This Row],[HC_ID]]&": - "&Tabella4[[#This Row],[Detail]]&" con selettore: "&Tabella4[[#This Row],[Rejected Element]] -> #N/A | AK6: =Tabella4[[#This Row],[HC_ID]]&": "&Tabella4[[#This Row],[Share URL]] -> #N/A | AL6: =Tabella4[[#This Row],[HC_ID]]&": "&Tabella4[[#This Row],[Soluzione note aggiuntive]] -> #N/A
A7: =Tabella4[[#This Row],[UNI CEI EN 301549]]&Tabella4[[#This Row],[Servizio]] -> 11.2.5.8.1S002 Registrazione | B7: =Tabella4[[#This Row],[IssueID]]&Tabella4[[#This Row],[Servizio]] -> S002 Registrazione | C7: AAD006 | D7: ="(#"&Tabella4[[#This Row],['#ID]]&")" -> (#AAD006) | E7: Android | F7: AA | G7: 2.5.8 | H7: 11.2.5.8.1 | I7: 2 - Serious | J7: Blind;Low Vision;Mobility | K7: Touch target | M7: [654,225][781,271] | N7: https://drive.google.com/file/d/1Ky3onw1yTzntxdtp2e6NbCHhxzGdkenw/view?usp=drive_link | O7: Home password dimenticata.txt | P7: #1 | Q7: Accessibility Scanner | S7: https://support.google.com/accessibility/android/answer/7101858?sjid=12879261749095892834-EU | T7: Aumenta le dimensioni minime degli elementi cliccabili o aggiungi padding/click area extra invisibile per raggiungere la dimensione minima. | U7: =COUNTIFS(Tabella4[Rejected Element],Tabella4[[#This Row],[Rejected Element]]) -> 14 | V7: S002 Registrazione | X7: =Tabella4[[#This Row],[User Impact]] -> 2 - Serious | Y7: =_xlfn.CONCAT("APP INDABOX ANDROID - ",Tabella4[[#This Row],[UNI CEI EN 301549]]," ",_xlfn.XLOOKUP(Tabella4[[#This Row],[Criterio]],Tabella5[ID],Tabella5[Criterio di successo],"")," - ",Tabella4[[#This Row],[Servizio]]) -> APP INDABOX ANDROID - 11.2.5.8.1 Dimensione dell'obiettivo (minimo) - S002 Registrazione | Z7: =_xlfn.CONCAT(Tabella4[[#This Row],[Titolo Defect]]," ",Tabella4[[#This Row],[ID defectXsilk]],CHAR(10),Tabella4[[#This Row],[Servizio]],CHAR(10),_xlfn.CONCAT("Requisito: WCAG ",Tabella4[[#This Row],[Criterio]],CHAR(10),"Disabilità afflitte: ",Tabella4[[#This Row],[Disabilities]],CHAR(10),"Impatto Utente: ",Tabella4[[#This Row],[User Impact]],CHAR(10),CHAR(10),"Descrizione: ",Tabella4[[#This Row],[Titolo]]," - ",Tabella4[[#This Row],[Descrizione]],CHAR(10),CHAR(10),"Esempio di violazione individuata sull'oggetto: ",CHAR(10)," - ",Tabella4[[#This Row],[Detail]]," con selettore: ",CHAR(10),Tabella4[[#This Row],[Rejected Element]],CHAR(10),CHAR(10),"Dettaglio + screenshot (accedere con le seguenti credenziali: user, axeposte@gmail.com; password, Poste2024!): ",Tabella4[[#This Row],[Share URL]],CHAR(10)),CHAR(10),"Possibile metodologia risolutiva:"&CHAR(10),Tabella4[[#This Row],[Soluzione note aggiuntive]],CHAR(10),CHAR(10),"File di log (occorrenze rilevate: "&COUNTIF(Tabella4[ID Silk],Tabella4[[#This Row],[ID Silk]])&"): https://posteitaliane.sharepoint.com/:x:/r/teams/ACCESSIBILITRISULTATIVERIFICHETECNICHE/Shared%20Documents/TGPOSTE_APP/TGPOSTE_APP/LOG/Log.xlsx?d=w630300a71bd74143a1658fe5ab688bc4&csf=1&web=1&e=Y9XHGL",CHAR(10),CHAR(10),"Link al dettaglio requisito WCAG: ",_xlfn.XLOOKUP(Tabella4[[#This Row],[UNI CEI EN 301549]],'Dati input'!F:F,'Dati input'!H:H,"",0)) -> APP INDABOX ANDROID - 11.2.5.8.1 Dimensione dell'obiettivo (minimo) - S002 Registrazione (#AAD006) S002 Registrazione Requisito: WCAG 2.5.8 Disabilità afflitte: Blind;Low Vision;Mobility Impatto Utente: 2 - Serious Descrizione: Touch target - Esempio di violazione individuata sull'oggetto: - https://drive.google.com/file/d/1Ky3onw1yTzntxdtp2e6NbCHhxzGdkenw/view?usp=drive_link con selettore: [654,225][781,271] Dettaglio + screenshot (accedere con le seguenti credenziali: user, axeposte@gmail.com; password, Poste2024!): Possibile metodologia risolutiva: Aumenta le dimensioni minime degli elementi cliccabili o aggiungi padding/click area extra invisibile per raggiungere la dimensione minima. File di log (occorrenze rilevate: 31): https://posteitaliane.sharepoint.com/:x:/r/teams/ACCESSIBILITRISULTATIVERIFICHETECNICHE/Shared%20Documents/TGPOSTE_APP/TGPOSTE_APP/LOG/Log.xlsx?d=w630300a71bd74143a1658fe5ab688bc4&csf=1&web=1&e=Y9XHGL Link al dettaglio requisito WCAG: | AE7: =_xlfn.XLOOKUP(Tabella4[[#This Row],[ID Silk]],outTable[ID Silk],outTable[Numero ticket ],,0,1) -> #N/A | AH7: =Tabella4[[#This Row],[Caricato su Silk]]&Tabella4[[#This Row],[HC_01]] -> #N/A | AI7: =Tabella4[[#This Row],[HC_ID]]&": "&Tabella4[[#This Row],[Descrizione]] -> #N/A | AJ7: =Tabella4[[#This Row],[HC_ID]]&": - "&Tabella4[[#This Row],[Detail]]&" con selettore: "&Tabella4[[#This Row],[Rejected Element]] -> #N/A | AK7: =Tabella4[[#This Row],[HC_ID]]&": "&Tabella4[[#This Row],[Share URL]] -> #N/A | AL7: =Tabella4[[#This Row],[HC_ID]]&": "&Tabella4[[#This Row],[Soluzione note aggiuntive]] -> #N/A
A8: =Tabella4[[#This Row],[UNI CEI EN 301549]]&Tabella4[[#This Row],[Servizio]] -> 11.2.5.8.1S002 Registrazione | B8: =Tabella4[[#This Row],[IssueID]]&Tabella4[[#This Row],[Servizio]] -> S002 Registrazione | C8: AAD007 | D8: ="(#"&Tabella4[[#This Row],['#ID]]&")" -> (#AAD007) | E8: Android | F8: AA | G8: 2.5.8 | H8: 11.2.5.8.1 | I8: 2 - Serious | J8: Blind;Low Vision;Mobility | K8: Touch target | M8: [822,225][918,271] | N8: https://drive.google.com/file/d/1Ky3onw1yTzntxdtp2e6NbCHhxzGdkenw/view?usp=drive_link | O8: Home password dimenticata.txt | P8: #1 | Q8: Accessibility Scanner | S8: https://support.google.com/accessibility/android/answer/7101858?sjid=12879261749095892834-EU | T8: Aumenta le dimensioni minime degli elementi cliccabili o aggiungi padding/click area extra invisibile per raggiungere la dimensione minima. | U8: =COUNTIFS(Tabella4[Rejected Element],Tabella4[[#This Row],[Rejected Element]]) -> 14 | V8: S002 Registrazione | X8: =Tabella4[[#This Row],[User Impact]] -> 2 - Serious | Y8: =_xlfn.CONCAT("APP INDABOX ANDROID - ",Tabella4[[#This Row],[UNI CEI EN 301549]]," ",_xlfn.XLOOKUP(Tabella4[[#This Row],[Criterio]],Tabella5[ID],Tabella5[Criterio di successo],"")," - ",Tabella4[[#This Row],[Servizio]]) -> APP INDABOX ANDROID - 11.2.5.8.1 Dimensione dell'obiettivo (minimo) - S002 Registrazione | Z8: =_xlfn.CONCAT(Tabella4[[#This Row],[Titolo Defect]]," ",Tabella4[[#This Row],[ID defectXsilk]],CHAR(10),Tabella4[[#This Row],[Servizio]],CHAR(10),_xlfn.CONCAT("Requisito: WCAG ",Tabella4[[#This Row],[Criterio]],CHAR(10),"Disabilità afflitte: ",Tabella4[[#This Row],[Disabilities]],CHAR(10),"Impatto Utente: ",Tabella4[[#This Row],[User Impact]],CHAR(10),CHAR(10),"Descrizione: ",Tabella4[[#This Row],[Titolo]]," - ",Tabella4[[#This Row],[Descrizione]],CHAR(10),CHAR(10),"Esempio di violazione individuata sull'oggetto: ",CHAR(10)," - ",Tabella4[[#This Row],[Detail]]," con selettore: ",CHAR(10),Tabella4[[#This Row],[Rejected Element]],CHAR(10),CHAR(10),"Dettaglio + screenshot (accedere con le seguenti credenziali: user, axeposte@gmail.com; password, Poste2024!): ",Tabella4[[#This Row],[Share URL]],CHAR(10)),CHAR(10),"Possibile metodologia risolutiva:"&CHAR(10),Tabella4[[#This Row],[Soluzione note aggiuntive]],CHAR(10),CHAR(10),"File di log (occorrenze rilevate: "&COUNTIF(Tabella4[ID Silk],Tabella4[[#This Row],[ID Silk]])&"): https://posteitaliane.sharepoint.com/:x:/r/teams/ACCESSIBILITRISULTATIVERIFICHETECNICHE/Shared%20Documents/TGPOSTE_APP/TGPOSTE_APP/LOG/Log.xlsx?d=w630300a71bd74143a1658fe5ab688bc4&csf=1&web=1&e=Y9XHGL",CHAR(10),CHAR(10),"Link al dettaglio requisito WCAG: ",_xlfn.XLOOKUP(Tabella4[[#This Row],[UNI CEI EN 301549]],'Dati input'!F:F,'Dati input'!H:H,"",0)) -> APP INDABOX ANDROID - 11.2.5.8.1 Dimensione dell'obiettivo (minimo) - S002 Registrazione (#AAD007) S002 Registrazione Requisito: WCAG 2.5.8 Disabilità afflitte: Blind;Low Vision;Mobility Impatto Utente: 2 - Serious Descrizione: Touch target - Esempio di violazione individuata sull'oggetto: - https://drive.google.com/file/d/1Ky3onw1yTzntxdtp2e6NbCHhxzGdkenw/view?usp=drive_link con selettore: [822,225][918,271] Dettaglio + screenshot (accedere con le seguenti credenziali: user, axeposte@gmail.com; password, Poste2024!): Possibile metodologia risolutiva: Aumenta le dimensioni minime degli elementi cliccabili o aggiungi padding/click area extra invisibile per raggiungere la dimensione minima. File di log (occorrenze rilevate: 31): https://posteitaliane.sharepoint.com/:x:/r/teams/ACCESSIBILITRISULTATIVERIFICHETECNICHE/Shared%20Documents/TGPOSTE_APP/TGPOSTE_APP/LOG/Log.xlsx?d=w630300a71bd74143a1658fe5ab688bc4&csf=1&web=1&e=Y9XHGL Link al dettaglio requisito WCAG: | AE8: =_xlfn.XLOOKUP(Tabella4[[#This Row],[ID Silk]],outTable[ID Silk],outTable[Numero ticket ],,0,1) -> #N/A | AH8: =Tabella4[[#This Row],[Caricato su Silk]]&Tabella4[[#This Row],[HC_01]] -> #N/A | AI8: =Tabella4[[#This Row],[HC_ID]]&": "&Tabella4[[#This Row],[Descrizione]] -> #N/A | AJ8: =Tabella4[[#This Row],[HC_ID]]&": - "&Tabella4[[#This Row],[Detail]]&" con selettore: "&Tabella4[[#This Row],[Rejected Element]] -> #N/A | AK8: =Tabella4[[#This Row],[HC_ID]]&": "&Tabella4[[#This Row],[Share URL]] -> #N/A | AL8: =Tabella4[[#This Row],[HC_ID]]&": "&Tabella4[[#This Row],[Soluzione note aggiuntive]] -> #N/A
A9: =Tabella4[[#This Row],[UNI CEI EN 301549]]&Tabella4[[#This Row],[Servizio]] -> 11.2.5.8.1S001 Accedi | B9: =Tabella4[[#This Row],[IssueID]]&Tabella4[[#This Row],[Servizio]] -> S001 Accedi | C9: AAD008 | D9: ="(#"&Tabella4[[#This Row],['#ID]]&")" -> (#AAD008) | E9: Android | F9: AA | G9: 2.5.8 | H9: 11.2.5.8.1 | I9: 2 - Serious | J9: Blind;Low Vision;Mobility | K9: Touch target | M9: [836,139][1028,181] | N9: https://drive.google.com/file/d/1MhJPH9Vg8MXuazsMdsQsob8Jy-l-XuIz/view?usp=drive_link | O9: Home prezzi.txt | P9: #2 | Q9: Accessibility Scanner | S9: https://support.google.com/accessibility/android/answer/7101858?sjid=12879261749095892834-EU | T9: Aumenta le dimensioni minime degli elementi cliccabili o aggiungi padding/click area extra invisibile per raggiungere la dimensione minima. | U9: =COUNTIFS(Tabella4[Rejected Element],Tabella4[[#This Row],[Rejected Element]]) -> 15 | V9: S001 Accedi | X9: =Tabella4[[#This Row],[User Impact]] -> 2 - Serious | Y9: =_xlfn.CONCAT("APP INDABOX ANDROID - ",Tabella4[[#This Row],[UNI CEI EN 301549]]," ",_xlfn.XLOOKUP(Tabella4[[#This Row],[Criterio]],Tabella5[ID],Tabella5[Criterio di successo],"")," - ",Tabella4[[#This Row],[Servizio]]) -> APP INDABOX ANDROID - 11.2.5.8.1 Dimensione dell'obiettivo (minimo) - S001 Accedi | Z9: =_xlfn.CONCAT(Tabella4[[#This Row],[Titolo Defect]]," ",Tabella4[[#This Row],[ID defectXsilk]],CHAR(10),Tabella4[[#This Row],[Servizio]],CHAR(10),_xlfn.CONCAT("Requisito: WCAG ",Tabella4[[#This Row],[Criterio]],CHAR(10),"Disabilità afflitte: ",Tabella4[[#This Row],[Disabilities]],CHAR(10),"Impatto Utente: ",Tabella4[[#This Row],[User Impact]],CHAR(10),CHAR(10),"Descrizione: ",Tabella4[[#This Row],[Titolo]]," - ",Tabella4[[#This Row],[Descrizione]],CHAR(10),CHAR(10),"Esempio di violazione individuata sull'oggetto: ",CHAR(10)," - ",Tabella4[[#This Row],[Detail]]," con selettore: ",CHAR(10),Tabella4[[#This Row],[Rejected Element]],CHAR(10),CHAR(10),"Dettaglio + screenshot (accedere con le seguenti credenziali: user, axeposte@gmail.com; password, Poste2024!): ",Tabella4[[#This Row],[Share URL]],CHAR(10)),CHAR(10),"Possibile metodologia risolutiva:"&CHAR(10),Tabella4[[#This Row],[Soluzione note aggiuntive]],CHAR(10),CHAR(10),"File di log (occorrenze rilevate: "&COUNTIF(Tabella4[ID Silk],Tabella4[[#This Row],[ID Silk]])&"): https://posteitaliane.sharepoint.com/:x:/r/teams/ACCESSIBILITRISULTATIVERIFICHETECNICHE/Shared%20Documents/TGPOSTE_APP/TGPOSTE_APP/LOG/Log.xlsx?d=w630300a71bd74143a1658fe5ab688bc4&csf=1&web=1&e=Y9XHGL",CHAR(10),CHAR(10),"Link al dettaglio requisito WCAG: ",_xlfn.XLOOKUP(Tabella4[[#This Row],[UNI CEI EN 301549]],'Dati input'!F:F,'Dati input'!H:H,"",0)) -> APP INDABOX ANDROID - 11.2.5.8.1 Dimensione dell'obiettivo (minimo) - S001 Accedi (#AAD008) S001 Accedi Requisito: WCAG 2.5.8 Disabilità afflitte: Blind;Low Vision;Mobility Impatto Utente: 2 - Serious Descrizione: Touch target - Esempio di violazione individuata sull'oggetto: - https://drive.google.com/file/d/1MhJPH9Vg8MXuazsMdsQsob8Jy-l-XuIz/view?usp=drive_link con selettore: [836,139][1028,181] Dettaglio + screenshot (accedere con le seguenti credenziali: user, axeposte@gmail.com; password, Poste2024!): Possibile metodologia risolutiva: Aumenta le dimensioni minime degli elementi cliccabili o aggiungi padding/click area extra invisibile per raggiungere la dimensione minima. File di log (occorrenze rilevate: 113): https://posteitaliane.sharepoint.com/:x:/r/teams/ACCESSIBILITRISULTATIVERIFICHETECNICHE/Shared%20Documents/TGPOSTE_APP/TGPOSTE_APP/LOG/Log.xlsx?d=w630300a71bd74143a1658fe5ab688bc4&csf=1&web=1&e=Y9XHGL Link al dettaglio requisito WCAG: | AE9: =_xlfn.XLOOKUP(Tabella4[[#This Row],[ID Silk]],outTable[ID Silk],outTable[Numero ticket ],,0,1) -> #N/A | AH9: =Tabella4[[#This Row],[Caricato su Silk]]&Tabella4[[#This Row],[HC_01]] -> #N/A | AI9: =Tabella4[[#This Row],[HC_ID]]&": "&Tabella4[[#This Row],[Descrizione]] -> #N/A | AJ9: =Tabella4[[#This Row],[HC_ID]]&": - "&Tabella4[[#This Row],[Detail]]&" con selettore: "&Tabella4[[#This Row],[Rejected Element]] -> #N/A | AK9: =Tabella4[[#This Row],[HC_ID]]&": "&Tabella4[[#This Row],[Share URL]] -> #N/A | AL9: =Tabella4[[#This Row],[HC_ID]]&": "&Tabella4[[#This Row],[Soluzione note aggiuntive]] -> #N/A
